Workbook

Sheet Slot Map
A1: SLOT MAP — JADWAL KELAS PER LANE | Z1: helper: jam 15-menit per lane — jangan diubah
A2: Baris = jam, kolom = hari. Tiap sel: age group · terisi/kapasitas (%) · coach · assist coach. Warna = status keterisian. Ganti center di B4. | Z2: 06:00 | AA2: =IF(COUNTIFS('Reguler Class Availability'!$L:$L,$B$4&"|- Lane 1 - *|"&Z2)>0,1,0) -> 0 | AB2: =AA2 -> 0
Z3: 06:15 | AA3: =IF(COUNTIFS('Reguler Class Availability'!$L:$L,$B$4&"|- Lane 1 - *|"&Z3)>0,1,0) -> 0 | AB3: =AA3+AB2 -> 0
A4: Center | B4: KLM | C4: ← pilih center | Z4: 06:30 | AA4: =IF(COUNTIFS('Reguler Class Availability'!$L:$L,$B$4&"|- Lane 1 - *|"&Z4)>0,1,0) -> 0 | AB4: =AA4+AB3 -> 0
Z5: 06:45 | AA5: =IF(COUNTIFS('Reguler Class Availability'!$L:$L,$B$4&"|- Lane 1 - *|"&Z5)>0,1,0) -> 0 | AB5: =AA5+AB4 -> 0
A6: Ringkasan | B6: Utilisasi center | C6: Kursi terisi / kapasitas | D6: Belum terisi | E6: Slot kosong | F6: Penuh | G6: Lebih kapasitas | H6: Tutup | Z6: 07:00 | AA6: =IF(COUNTIFS('Reguler Class Availability'!$L:$L,$B$4&"|- Lane 1 - *|"&Z6)>0,1,0) -> 0 | AB6: =AA6+AB5 -> 0
B7: =IFERROR(SUMIFS('Reguler Class Availability'!$G:$G,'Reguler Class Availability'!$A:$A,$B$4,'Reguler Class Availability'!$F:$F,">0")/SUMIFS('Reguler Class Availability'!$F:$F,'Reguler Class Availability'!$A:$A,$B$4,'Reguler Class Availability'!$F:$F,">0"),"–") -> 0.52839821 | C7: =SUMIFS('Reguler Class Availability'!$G:$G,'Reguler Class Availability'!$A:$A,$B$4,'Reguler Class Availability'!$F:$F,">0")&" / "&SUMIFS('Reguler Class Availability'!$F:$F,'Reguler Class Availability'!$A:$A,$B$4,'Reguler Class Availability'!$F:$F,">0") -> 828 / 1567 | D7: =COUNTIF($R$1:$X$1000,"Belum terisi") -> 62 | E7: =COUNTIF($R$1:$X$1000,"Kosong") -> 56 | F7: =COUNTIF($R$1:$X$1000,"Penuh") -> 131 | G7: =COUNTIF($R$1:$X$1000,"Lebih") -> 24 | H7: =COUNTIF($R$1:$X$1000,"Tutup") -> 46 | Z7: 07:15 | AA7: =IF(COUNTIFS('Reguler Class Availability'!$L:$L,$B$4&"|- Lane 1 - *|"&Z7)>0,1,0) -> 0 | AB7: =AA7+AB6 -> 0
Z8: 07:30 | AA8: =IF(COUNTIFS('Reguler Class Availability'!$L:$L,$B$4&"|- Lane 1 - *|"&Z8)>0,1,0) -> 1 | AB8: =AA8+AB7 -> 1
A9: Warna | B9: Belum terisi (kelas ada, 0 murid) | C9: Slot kosong (belum ada kelas) | D9: Terisi < 60% | E9: Terisi 60–99% | F9: Penuh | G9: Lebih kapasitas | H9: Tutup (kapasitas 0) | Z9: 07:45 | AA9: =IF(COUNTIFS('Reguler Class Availability'!$L:$L,$B$4&"|- Lane 1 - *|"&Z9)>0,1,0) -> 0 | AB9: =AA9+AB8 -> 1
A10: Age group | B10: Baby · 6–17 bulan | C10: Tiny · 18–36 bulan | D10: Little · 3–5 tahun | E10: Kids · 5–8+ tahun | F10: Star · 9–12 tahun | Z10: 08:00 | AA10: =IF(COUNTIFS('Reguler Class Availability'!$L:$L,$B$4&"|- Lane 1 - *|"&Z10)>0,1,0) -> 0 | AB10: =AA10+AB9 -> 1
Z11: 08:15 | AA11: =IF(COUNTIFS('Reguler Class Availability'!$L:$L,$B$4&"|- Lane 1 - *|"&Z11)>0,1,0) -> 1 | AB11: =AA11+AB10 -> 2
A12: LANE 1 | C12: ="Utilisasi lane: "&IFERROR(TEXT(SUMIFS('Reguler Class Availability'!$G:$G,'Reguler Class Availability'!$A:$A,$B$4,'Reguler Class Availability'!$C:$C,"- Lane 1 - *",'Reguler Class Availability'!$F:$F,">0")/SUMIFS('Reguler Class Availability'!$F:$F,'Reguler Class Availability'!$A:$A,$B$4,'Reguler Class Availability'!$C:$C,"- Lane 1 - *",'Reguler Class Availability'!$F:$F,">0"),"0%"),"–")&" · Belum terisi: "&COUNTIF($R$14:$X$29,"Belum terisi")&" · Slot kosong: "&COUNTIF($R$14:$X$29,"Kosong") -> Utilisasi lane: 30% · Belum terisi: 15 · Slot kosong: 27 | Z12: 08:30 | AA12: =IF(COUNTIFS('Reguler Class Availability'!$L:$L,$B$4&"|- Lane 1 - *|"&Z12)>0,1,0) -> 0 | AB12: =AA12+AB11 -> 2
A13: Jam | B13: Senin | C13: Selasa | D13: Rabu | E13: Kamis | F13: Jumat | G13: Sabtu | H13: Minggu | Z13: 08:45 | AA13: =IF(COUNTIFS('Reguler Class Availability'!$L:$L,$B$4&"|- Lane 1 - *|"&Z13)>0,1,0) -> 0 | AB13: =AA13+AB12 -> 2
A14: =IFERROR(INDEX($Z$2:$Z$61,MATCH(1,$AB$2:$AB$61,0)),"") -> 07:30 | B14: =IF(J14="","",IF(R14="Tidak dibuka","–",IF(INDEX('Reguler Class Availability'!$B:$B,J14)&""="","Kosong",PROPER(INDEX('Reguler Class Availability'!$B:$B,J14)&""))&" "&IFERROR(--(INDEX('Reguler Class Availability'!$G:$G,J14)&""),0)&"/"&IFERROR(--(INDEX('Reguler Class Availability'!$F:$F,J14)&""),0)&IF(IFERROR(--(INDEX('Reguler Class Availability'!$F:$F,J14)&""),0)>0," ("&TEXT(IFERROR(--(INDEX('Reguler Class Availability'!$G:$G,J14)&""),0)/IFERROR(--(INDEX('Reguler Class Availability'!$F:$F,J14)&""),0),"0%")&")","")&CHAR(10)&IF(INDEX('Reguler Class Availability'!$I:$I,J14)&""="","coach: –",PROPER(INDEX('Reguler Class Availability'!$I:$I,J14)&""))&IF(INDEX('Reguler Class Availability'!$J:$J,J14)&""="","",CHAR(10)&"asst: "&PROPER(INDEX('Reguler Class Availability'!$J:$J,J14)&"")))) -> Star 0/8 (0%) coach: – | C14: =IF(K14="","",IF(S14="Tidak dibuka","–",IF(INDEX('Reguler Class Availability'!$B:$B,K14)&""="","Kosong",PROPER(INDEX('Reguler Class Availability'!$B:$B,K14)&""))&" "&IFERROR(--(INDEX('Reguler Class Availability'!$G:$G,K14)&""),0)&"/"&IFERROR(--(INDEX('Reguler Class Availability'!$F:$F,K14)&""),0)&IF(IFERROR(--(INDEX('Reguler Class Availability'!$F:$F,K14)&""),0)>0," ("&TEXT(IFERROR(--(INDEX('Reguler Class Availability'!$G:$G,K14)&""),0)/IFERROR(--(INDEX('Reguler Class Availability'!$F:$F,K14)&""),0),"0%")&")","")&CHAR(10)&IF(INDEX('Reguler Class Availability'!$I:$I,K14)&""="","coach: –",PROPER(INDEX('Reguler Class Availability'!$I:$I,K14)&""))&IF(INDEX('Reguler Class Availability'!$J:$J,K14)&""="","",CHAR(10)&"asst: "&PROPER(INDEX('Reguler Class Availability'!$J:$J,K14)&"")))) -> Star 0/8 (0%) coach: – | D14: =IF(L14="","",IF(T14="Tidak dibuka","–",IF(INDEX('Reguler Class Availability'!$B:$B,L14)&""="","Kosong",PROPER(INDEX('Reguler Class Availability'!$B:$B,L14)&""))&" "&IFERROR(--(INDEX('Reguler Class Availability'!$G:$G,L14)&""),0)&"/"&IFERROR(--(INDEX('Reguler Class Availability'!$F:$F,L14)&""),0)&IF(IFERROR(--(INDEX('Reguler Class Availability'!$F:$F,L14)&""),0)>0," ("&TEXT(IFERROR(--(INDEX('Reguler Class Availability'!$G:$G,L14)&""),0)/IFERROR(--(INDEX('Reguler Class Availability'!$F:$F,L14)&""),0),"0%")&")","")&CHAR(10)&IF(INDEX('Reguler Class Availability'!$I:$I,L14)&""="","coach: –",PROPER(INDEX('Reguler Class Availability'!$I:$I,L14)&""))&IF(INDEX('Reguler Class Availability'!$J:$J,L14)&""="","",CHAR(10)&"asst: "&PROPER(INDEX('Reguler Class Availability'!$J:$J,L14)&"")))) -> Star 0/8 (0%) coach: – | E14: =IF(M14="","",IF(U14="Tidak dibuka","–",IF(INDEX('Reguler Class Availability'!$B:$B,M14)&""="","Kosong",PROPER(INDEX('Reguler Class Availability'!$B:$B,M14)&""))&" "&IFERROR(--(INDEX('Reguler Class Availability'!$G:$G,M14)&""),0)&"/"&IFERROR(--(INDEX('Reguler Class Availability'!$F:$F,M14)&""),0)&IF(IFERROR(--(INDEX('Reguler Class Availability'!$F:$F,M14)&""),0)>0," ("&TEXT(IFERROR(--(INDEX('Reguler Class Availability'!$G:$G,M14)&""),0)/IFERROR(--(INDEX('Reguler Class Availability'!$F:$F,M14)&""),0),"0%")&")","")&CHAR(10)&IF(INDEX('Reguler Class Availability'!$I:$I,M14)&""="","coach: –",PROPER(INDEX('Reguler Class Availability'!$I:$I,M14)&""))&IF(INDEX('Reguler Class Availability'!$J:$J,M14)&""="","",CHAR(10)&"asst: "&PROPER(INDEX('Reguler Class Availability'!$J:$J,M14)&"")))) -> Star 0/8 (0%) coach: – | F14: =IF(N14="","",IF(V14="Tidak dibuka","–",IF(INDEX('Reguler Class Availability'!$B:$B,N14)&""="","Kosong",PROPER(INDEX('Reguler Class Availability'!$B:$B,N14)&""))&" "&IFERROR(--(INDEX('Reguler Class Availability'!$G:$G,N14)&""),0)&"/"&IFERROR(--(INDEX('Reguler Class Availability'!$F:$F,N14)&""),0)&IF(IFERROR(--(INDEX('Reguler Class Availability'!$F:$F,N14)&""),0)>0," ("&TEXT(IFERROR(--(INDEX('Reguler Class Availability'!$G:$G,N14)&""),0)/IFERROR(--(INDEX('Reguler Class Availability'!$F:$F,N14)&""),0),"0%")&")","")&CHAR(10)&IF(INDEX('Reguler Class Availability'!$I:$I,N14)&""="","coach: –",PROPER(INDEX('Reguler Class Availability'!$I:$I,N14)&""))&IF(INDEX('Reguler Class Availability'!$J:$J,N14)&""="","",CHAR(10)&"asst: "&PROPER(INDEX('Reguler Class Availability'!$J:$J,N14)&"")))) -> Star 0/8 (0%) coach: – | G14: =IF(O14="","",IF(W14="Tidak dibuka","–",IF(INDEX('Reguler Class Availability'!$B:$B,O14)&""="","Kosong",PROPER(INDEX('Reguler Class Availability'!$B:$B,O14)&""))&" "&IFERROR(--(INDEX('Reguler Class Availability'!$G:$G,O14)&""),0)&"/"&IFERROR(--(INDEX('Reguler Class Availability'!$F:$F,O14)&""),0)&IF(IFERROR(--(INDEX('Reguler Class Availability'!$F:$F,O14)&""),0)>0," ("&TEXT(IFERROR(--(INDEX('Reguler Class Availability'!$G:$G,O14)&""),0)/IFERROR(--(INDEX('Reguler Class Availability'!$F:$F,O14)&""),0),"0%")&")","")&CHAR(10)&IF(INDEX('Reguler Class Availability'!$I:$I,O14)&""="","coach: –",PROPER(INDEX('Reguler Class Availability'!$I:$I,O14)&""))&IF(INDEX('Reguler Class Availability'!$J:$J,O14)&""="","",CHAR(10)&"asst: "&PROPER(INDEX('Reguler Class Availability'!$J:$J,O14)&"")))) -> Star 0/8 (0%) coach: – | H14: =IF(P14="","",IF(X14="Tidak dibuka","–",IF(INDEX('Reguler Class Availability'!$B:$B,P14)&""="","Kosong",PROPER(INDEX('Reguler Class Availability'!$B:$B,P14)&""))&" "&IFERROR(--(INDEX('Reguler Class Availability'!$G:$G,P14)&""),0)&"/"&IFERROR(--(INDEX('Reguler Class Availability'!$F:$F,P14)&""),0)&IF(IFERROR(--(INDEX('Reguler Class Availability'!$F:$F,P14)&""),0)>0," ("&TEXT(IFERROR(--(INDEX('Reguler Class Availability'!$G:$G,P14)&""),0)/IFERROR(--(INDEX('Reguler Class Availability'!$F:$F,P14)&""),0),"0%")&")","")&CHAR(10)&IF(INDEX('Reguler Class Availability'!$I:$I,P14)&""="","coach: –",PROPER(INDEX('Reguler Class Availability'!$I:$I,P14)&""))&IF(INDEX('Reguler Class Availability'!$J:$J,P14)&""="","",CHAR(10)&"asst: "&PROPER(INDEX('Reguler Class Availability'!$J:$J,P14)&"")))) -> Star 0/8 (0%) coach: – | J14: =IF($A14="","",IFERROR(MATCH($B$4&"|- Lane 1 - "&B$13&"|"&$A14,'Reguler Class Availability'!$L:$L,0),"")) -> 86 | K14: =IF($A14="","",IFERROR(MATCH($B$4&"|- Lane 1 - "&C$13&"|"&$A14,'Reguler Class Availability'!$L:$L,0),"")) -> 87 | L14: =IF($A14="","",IFERROR(MATCH($B$4&"|- Lane 1 - "&D$13&"|"&$A14,'Reguler Class Availability'!$L:$L,0),"")) -> 88 | M14: =IF($A14="","",IFERROR(MATCH($B$4&"|- Lane 1 - "&E$13&"|"&$A14,'Reguler Class Availability'!$L:$L,0),"")) -> 89 | N14: =IF($A14="","",IFERROR(MATCH($B$4&"|- Lane 1 - "&F$13&"|"&$A14,'Reguler Class Availability'!$L:$L,0),"")) -> 90 | O14: =IF($A14="","",IFERROR(MATCH($B$4&"|- Lane 1 - "&G$13&"|"&$A14,'Reguler Class Availability'!$L:$L,0),"")) -> 91 | P14: =IF($A14="","",IFERROR(MATCH($B$4&"|- Lane 1 - "&H$13&"|"&$A14,'Reguler Class Availability'!$L:$L,0),"")) -> 92 | R14: =IF(J14="","",IF(AND(IFERROR(--(INDEX('Reguler Class Availability'!$F:$F,J14)&""),0)=0,IFERROR(--(INDEX('Reguler Class Availability'!$G:$G,J14)&""),0)=0),IF(OR(INDEX('Reguler Class Availability'!$B:$B,J14)&""<>"",INDEX('Reguler Class Availability'!$I:$I,J14)&""<>""),"Tutup","Tidak dibuka"),IF(IFERROR(--(INDEX('Reguler Class Availability'!$G:$G,J14)&""),0)>IFERROR(--(INDEX('Reguler Class Availability'!$F:$F,J14)&""),0),"Lebih",IF(IFERROR(--(INDEX('Reguler Class Availability'!$G:$G,J14)&""),0)=IFERROR(--(INDEX('Reguler Class Availability'!$F:$F,J14)&""),0),"Penuh",IF(IFERROR(--(INDEX('Reguler Class Availability'!$G:$G,J14)&""),0)=0,IF(INDEX('Reguler Class Availability'!$B:$B,J14)&""="","Kosong","Belum terisi"),IF(IFERROR(--(INDEX('Reguler Class Availability'!$G:$G,J14)&""),0)/IFERROR(--(INDEX('Reguler Class Availability'!$F:$F,J14)&""),0)>=0.6,"Tinggi","Sebagian")))))) -> Belum terisi | S14: =IF(K14="","",IF(AND(IFERROR(--(INDEX('Reguler Class Availability'!$F:$F,K14)&""),0)=0,IFERROR(--(INDEX('Reguler Class Availability'!$G:$G,K14)&""),0)=0),IF(OR(INDEX('Reguler Class Availability'!$B:$B,K14)&""<>"",INDEX('Reguler Class Availability'!$I:$I,K14)&""<>""),"Tutup","Tidak dibuka"),IF(IFERROR(--(INDEX('Reguler Class Availability'!$G:$G,K14)&""),0)>IFERROR(--(INDEX('Reguler Class Availability'!$F:$F,K14)&""),0),"Lebih",IF(IFERROR(--(INDEX('Reguler Class Availability'!$G:$G,K14)&""),0)=IFERROR(--(INDEX('Reguler Class Availability'!$F:$F,K14)&""),0),"Penuh",IF(IFERROR(--(INDEX('Reguler Class Availability'!$G:$G,K14)&""),0)=0,IF(INDEX('Reguler Class Availability'!$B:$B,K14)&""="","Kosong","Belum terisi"),IF(IFERROR(--(INDEX('Reguler Class Availability'!$G:$G,K14)&""),0)/IFERROR(--(INDEX('Reguler Class Availability'!$F:$F,K14)&""),0)>=0.6,"Tinggi","Sebagian")))))) -> Belum terisi | T14: =IF(L14="","",IF(AND(IFERROR(--(INDEX('Reguler Class Availability'!$F:$F,L14)&""),0)=0,IFERROR(--(INDEX('Reguler Class Availability'!$G:$G,L14)&""),0)=0),IF(OR(INDEX('Reguler Class Availability'!$B:$B,L14)&""<>"",INDEX('Reguler Class Availability'!$I:$I,L14)&""<>""),"Tutup","Tidak dibuka"),IF(IFERROR(--(INDEX('Reguler Class Availability'!$G:$G,L14)&""),0)>IFERROR(--(INDEX('Reguler Class Availability'!$F:$F,L14)&""),0),"Lebih",IF(IFERROR(--(INDEX('Reguler Class Availability'!$G:$G,L14)&""),0)=IFERROR(--(INDEX('Reguler Class Availability'!$F:$F,L14)&""),0),"Penuh",IF(IFERROR(--(INDEX('Reguler Class Availability'!$G:$G,L14)&""),0)=0,IF(INDEX('Reguler Class Availability'!$B:$B,L14)&""="","Kosong","Belum terisi"),IF(IFERROR(--(INDEX('Reguler Class Availability'!$G:$G,L14)&""),0)/IFERROR(--(INDEX('Reguler Class Availability'!$F:$F,L14)&""),0)>=0.6,"Tinggi","Sebagian")))))) -> Belum terisi | U14: =IF(M14="","",IF(AND(IFERROR(--(INDEX('Reguler Class Availability'!$F:$F,M14)&""),0)=0,IFERROR(--(INDEX('Reguler Class Availability'!$G:$G,M14)&""),0)=0),IF(OR(INDEX('Reguler Class Availability'!$B:$B,M14)&""<>"",INDEX('Reguler Class Availability'!$I:$I,M14)&""<>""),"Tutup","Tidak dibuka"),IF(IFERROR(--(INDEX('Reguler Class Availability'!$G:$G,M14)&""),0)>IFERROR(--(INDEX('Reguler Class Availability'!$F:$F,M14)&""),0),"Lebih",IF(IFERROR(--(INDEX('Reguler Class Availability'!$G:$G,M14)&""),0)=IFERROR(--(INDEX('Reguler Class Availability'!$F:$F,M14)&""),0),"Penuh",IF(IFERROR(--(INDEX('Reguler Class Availability'!$G:$G,M14)&""),0)=0,IF(INDEX('Reguler Class Availability'!$B:$B,M14)&""="","Kosong","Belum terisi"),IF(IFERROR(--(INDEX('Reguler Class Availability'!$G:$G,M14)&""),0)/IFERROR(--(INDEX('Reguler Class Availability'!$F:$F,M14)&""),0)>=0.6,"Tinggi","Sebagian")))))) -> Belum terisi | V14: =IF(N14="","",IF(AND(IFERROR(--(INDEX('Reguler Class Availability'!$F:$F,N14)&""),0)=0,IFERROR(--(INDEX('Reguler Class Availability'!$G:$G,N14)&""),0)=0),IF(OR(INDEX('Reguler Class Availability'!$B:$B,N14)&""<>"",INDEX('Reguler Class Availability'!$I:$I,N14)&""<>""),"Tutup","Tidak dibuka"),IF(IFERROR(--(INDEX('Reguler Class Availability'!$G:$G,N14)&""),0)>IFERROR(--(INDEX('Reguler Class Availability'!$F:$F,N14)&""),0),"Lebih",IF(IFERROR(--(INDEX('Reguler Class Availability'!$G:$G,N14)&""),0)=IFERROR(--(INDEX('Reguler Class Availability'!$F:$F,N14)&""),0),"Penuh",IF(IFERROR(--(INDEX('Reguler Class Availability'!$G:$G,N14)&""),0)=0,IF(INDEX('Reguler Class Availability'!$B:$B,N14)&""="","Kosong","Belum terisi"),IF(IFERROR(--(INDEX('Reguler Class Availability'!$G:$G,N14)&""),0)/IFERROR(--(INDEX('Reguler Class Availability'!$F:$F,N14)&""),0)>=0.6,"Tinggi","Sebagian")))))) -> Belum terisi | W14: =IF(O14="","",IF(AND(IFERROR(--(INDEX('Reguler Class Availability'!$F:$F,O14)&""),0)=0,IFERROR(--(INDEX('Reguler Class Availability'!$G:$G,O14)&""),0)=0),IF(OR(INDEX('Reguler Class Availability'!$B:$B,O14)&""<>"",INDEX('Reguler Class Availability'!$I:$I,O14)&""<>""),"Tutup","Tidak dibuka"),IF(IFERROR(--(INDEX('Reguler Class Availability'!$G:$G,O14)&""),0)>IFERROR(--(INDEX('Reguler Class Availability'!$F:$F,O14)&""),0),"Lebih",IF(IFERROR(--(INDEX('Reguler Class Availability'!$G:$G,O14)&""),0)=IFERROR(--(INDEX('Reguler Class Availability'!$F:$F,O14)&""),0),"Penuh",IF(IFERROR(--(INDEX('Reguler Class Availability'!$G:$G,O14)&""),0)=0,IF(INDEX('Reguler Class Availability'!$B:$B,O14)&""="","Kosong","Belum terisi"),IF(IFERROR(--(INDEX('Reguler Class Availability'!$G:$G,O14)&""),0)/IFERROR(--(INDEX('Reguler Class Availability'!$F:$F,O14)&""),0)>=0.6,"Tinggi","Sebagian")))))) -> Belum terisi | X14: =IF(P14="","",IF(AND(IFERROR(--(INDEX('Reguler Class Availability'!$F:$F,P14)&""),0)=0,IFERROR(--(INDEX('Reguler Class Availability'!$G:$G,P14)&""),0)=0),IF(OR(INDEX('Reguler Class Availability'!$B:$B,P14)&""<>"",INDEX('Reguler Class Availability'!$I:$I,P14)&""<>""),"Tutup","Tidak dibuka"),IF(IFERROR(--(INDEX('Reguler Class Availability'!$G:$G,P14)&""),0)>IFERROR(--(INDEX('Reguler Class Availability'!$F:$F,P14)&""),0),"Lebih",IF(IFERROR(--(INDEX('Reguler Class Availability'!$G:$G,P14)&""),0)=IFERROR(--(INDEX('Reguler Class Availability'!$F:$F,P14)&""),0),"Penuh",IF(IFERROR(--(INDEX('Reguler Class Availability'!$G:$G,P14)&""),0)=0,IF(INDEX('Reguler Class Availability'!$B:$B,P14)&""="","Kosong","Belum terisi"),IF(IFERROR(--(INDEX('Reguler Class Availability'!$G:$G,P14)&""),0)/IFERROR(--(INDEX('Reguler Class Availability'!$F:$F,P14)&""),0)>=0.6,"Tinggi","Sebagian")))))) -> Belum terisi | Z14: 09:00 | AA14: =IF(COUNTIFS('Reguler Class Availability'!$L:$L,$B$4&"|- Lane 1 - *|"&Z14)>0,1,0) -> 1 | AB14: =AA14+AB13 -> 3
A15: =IFERROR(INDEX($Z$2:$Z$61,MATCH(2,$AB$2:$AB$61,0)),"") -> 08:15 | B15: =IF(J15="","",IF(R15="Tidak dibuka","–",IF(INDEX('Reguler Class Availability'!$B:$B,J15)&""="","Kosong",PROPER(INDEX('Reguler Class Availability'!$B:$B,J15)&""))&" "&IFERROR(--(INDEX('Reguler Class Availability'!$G:$G,J15)&""),0)&"/"&IFERROR(--(INDEX('Reguler Class Availability'!$F:$F,J15)&""),0)&IF(IFERROR(--(INDEX('Reguler Class Availability'!$F:$F,J15)&""),0)>0," ("&TEXT(IFERROR(--(INDEX('Reguler Class Availability'!$G:$G,J15)&""),0)/IFERROR(--(INDEX('Reguler Class Availability'!$F:$F,J15)&""),0),"0%")&")","")&CHAR(10)&IF(INDEX('Reguler Class Availability'!$I:$I,J15)&""="","coach: –",PROPER(INDEX('Reguler Class Availability'!$I:$I,J15)&""))&IF(INDEX('Reguler Class Availability'!$J:$J,J15)&""="","",CHAR(10)&"asst: "&PROPER(INDEX('Reguler Class Availability'!$J:$J,J15)&"")))) -> – | C15: =IF(K15="","",IF(S15="Tidak dibuka","–",IF(INDEX('Reguler Class Availability'!$B:$B,K15)&""="","Kosong",PROPER(INDEX('Reguler Class Availability'!$B:$B,K15)&""))&" "&IFERROR(--(INDEX('Reguler Class Availability'!$G:$G,K15)&""),0)&"/"&IFERROR(--(INDEX('Reguler Class Availability'!$F:$F,K15)&""),0)&IF(IFERROR(--(INDEX('Reguler Class Availability'!$F:$F,K15)&""),0)>0," ("&TEXT(IFERROR(--(INDEX('Reguler Class Availability'!$G:$G,K15)&""),0)/IFERROR(--(INDEX('Reguler Class Availability'!$F:$F,K15)&""),0),"0%")&")","")&CHAR(10)&IF(INDEX('Reguler Class Availability'!$I:$I,K15)&""="","coach: –",PROPER(INDEX('Reguler Class Availability'!$I:$I,K15)&""))&IF(INDEX('Reguler Class Availability'!$J:$J,K15)&""="","",CHAR(10)&"asst: "&PROPER(INDEX('Reguler Class Availability'!$J:$J,K15)&"")))) -> – | D15: =IF(L15="","",IF(T15="Tidak dibuka","–",IF(INDEX('Reguler Class Availability'!$B:$B,L15)&""="","Kosong",PROPER(INDEX('Reguler Class Availability'!$B:$B,L15)&""))&" "&IFERROR(--(INDEX('Reguler Class Availability'!$G:$G,L15)&""),0)&"/"&IFERROR(--(INDEX('Reguler Class Availability'!$F:$F,L15)&""),0)&IF(IFERROR(--(INDEX('Reguler Class Availability'!$F:$F,L15)&""),0)>0," ("&TEXT(IFERROR(--(INDEX('Reguler Class Availability'!$G:$G,L15)&""),0)/IFERROR(--(INDEX('Reguler Class Availability'!$F:$F,L15)&""),0),"0%")&")","")&CHAR(10)&IF(INDEX('Reguler Class Availability'!$I:$I,L15)&""="","coach: –",PROPER(INDEX('Reguler Class Availability'!$I:$I,L15)&""))&IF(INDEX('Reguler Class Availability'!$J:$J,L15)&""="","",CHAR(10)&"asst: "&PROPER(INDEX('Reguler Class Availability'!$J:$J,L15)&"")))) -> – | E15: =IF(M15="","",IF(U15="Tidak dibuka","–",IF(INDEX('Reguler Class Availability'!$B:$B,M15)&""="","Kosong",PROPER(INDEX('Reguler Class Availability'!$B:$B,M15)&""))&" "&IFERROR(--(INDEX('Reguler Class Availability'!$G:$G,M15)&""),0)&"/"&IFERROR(--(INDEX('Reguler Class Availability'!$F:$F,M15)&""),0)&IF(IFERROR(--(INDEX('Reguler Class Availability'!$F:$F,M15)&""),0)>0," ("&TEXT(IFERROR(--(INDEX('Reguler Class Availability'!$G:$G,M15)&""),0)/IFERROR(--(INDEX('Reguler Class Availability'!$F:$F,M15)&""),0),"0%")&")","")&CHAR(10)&IF(INDEX('Reguler Class Availability'!$I:$I,M15)&""="","coach: –",PROPER(INDEX('Reguler Class Availability'!$I:$I,M15)&""))&IF(INDEX('Reguler Class Availability'!$J:$J,M15)&""="","",CHAR(10)&"asst: "&PROPER(INDEX('Reguler Class Availability'!$J:$J,M15)&"")))) -> – | F15: =IF(N15="","",IF(V15="Tidak dibuka","–",IF(INDEX('Reguler Class Availability'!$B:$B,N15)&""="","Kosong",PROPER(INDEX('Reguler Class Availability'!$B:$B,N15)&""))&" "&IFERROR(--(INDEX('Reguler Class Availability'!$G:$G,N15)&""),0)&"/"&IFERROR(--(INDEX('Reguler Class Availability'!$F:$F,N15)&""),0)&IF(IFERROR(--(INDEX('Reguler Class Availability'!$F:$F,N15)&""),0)>0," ("&TEXT(IFERROR(--(INDEX('Reguler Class Availability'!$G:$G,N15)&""),0)/IFERROR(--(INDEX('Reguler Class Availability'!$F:$F,N15)&""),0),"0%")&")","")&CHAR(10)&IF(INDEX('Reguler Class Availability'!$I:$I,N15)&""="","coach: –",PROPER(INDEX('Reguler Class Availability'!$I:$I,N15)&""))&IF(INDEX('Reguler Class Availability'!$J:$J,N15)&""="","",CHAR(10)&"asst: "&PROPER(INDEX('Reguler Class Availability'!$J:$J,N15)&"")))) -> – | G15: =IF(O15="","",IF(W15="Tidak dibuka","–",IF(INDEX('Reguler Class Availability'!$B:$B,O15)&""="","Kosong",PROPER(INDEX('Reguler Class Availability'!$B:$B,O15)&""))&" "&IFERROR(--(INDEX('Reguler Class Availability'!$G:$G,O15)&""),0)&"/"&IFERROR(--(INDEX('Reguler Class Availability'!$F:$F,O15)&""),0)&IF(IFERROR(--(INDEX('Reguler Class Availability'!$F:$F,O15)&""),0)>0," ("&TEXT(IFERROR(--(INDEX('Reguler Class Availability'!$G:$G,O15)&""),0)/IFERROR(--(INDEX('Reguler Class Availability'!$F:$F,O15)&""),0),"0%")&")","")&CHAR(10)&IF(INDEX('Reguler Class Availability'!$I:$I,O15)&""="","coach: –",PROPER(INDEX('Reguler Class Availability'!$I:$I,O15)&""))&IF(INDEX('Reguler Class Availability'!$J:$J,O15)&""="","",CHAR(10)&"asst: "&PROPER(INDEX('Reguler Class Availability'!$J:$J,O15)&"")))) -> – | H15: =IF(P15="","",IF(X15="Tidak dibuka","–",IF(INDEX('Reguler Class Availability'!$B:$B,P15)&""="","Kosong",PROPER(INDEX('Reguler Class Availability'!$B:$B,P15)&""))&" "&IFERROR(--(INDEX('Reguler Class Availability'!$G:$G,P15)&""),0)&"/"&IFERROR(--(INDEX('Reguler Class Availability'!$F:$F,P15)&""),0)&IF(IFERROR(--(INDEX('Reguler Class Availability'!$F:$F,P15)&""),0)>0," ("&TEXT(IFERROR(--(INDEX('Reguler Class Availability'!$G:$G,P15)&""),0)/IFERROR(--(INDEX('Reguler Class Availability'!$F:$F,P15)&""),0),"0%")&")","")&CHAR(10)&IF(INDEX('Reguler Class Availability'!$I:$I,P15)&""="","coach: –",PROPER(INDEX('Reguler Class Availability'!$I:$I,P15)&""))&IF(INDEX('Reguler Class Availability'!$J:$J,P15)&""="","",CHAR(10)&"asst: "&PROPER(INDEX('Reguler Class Availability'!$J:$J,P15)&"")))) -> – | J15: =IF($A15="","",IFERROR(MATCH($B$4&"|- Lane 1 - "&B$13&"|"&$A15,'Reguler Class Availability'!$L:$L,0),"")) -> 2 | K15: =IF($A15="","",IFERROR(MATCH($B$4&"|- Lane 1 - "&C$13&"|"&$A15,'Reguler Class Availability'!$L:$L,0),"")) -> 14 | L15: =IF($A15="","",IFERROR(MATCH($B$4&"|- Lane 1 - "&D$13&"|"&$A15,'Reguler Class Availability'!$L:$L,0),"")) -> 26 | M15: =IF($A15="","",IFERROR(MATCH($B$4&"|- Lane 1 - "&E$13&"|"&$A15,'Reguler Class Availability'!$L:$L,0),"")) -> 38 | N15: =IF($A15="","",IFERROR(MATCH($B$4&"|- Lane 1 - "&F$13&"|"&$A15,'Reguler Class Availability'!$L:$L,0),"")) -> 50 | O15: =IF($A15="","",IFERROR(MATCH($B$4&"|- Lane 1 - "&G$13&"|"&$A15,'Reguler Class Availability'!$L:$L,0),"")) -> 62 | P15: =IF($A15="","",IFERROR(MATCH($B$4&"|- Lane 1 - "&H$13&"|"&$A15,'Reguler Class Availability'!$L:$L,0),"")) -> 74 | R15: =IF(J15="","",IF(AND(IFERROR(--(INDEX('Reguler Class Availability'!$F:$F,J15)&""),0)=0,IFERROR(--(INDEX('Reguler Class Availability'!$G:$G,J15)&""),0)=0),IF(OR(INDEX('Reguler Class Availability'!$B:$B,J15)&""<>"",INDEX('Reguler Class Availability'!$I:$I,J15)&""<>""),"Tutup","Tidak dibuka"),IF(IFERROR(--(INDEX('Reguler Class Availability'!$G:$G,J15)&""),0)>IFERROR(--(INDEX('Reguler Class Availability'!$F:$F,J15)&""),0),"Lebih",IF(IFERROR(--(INDEX('Reguler Class Availability'!$G:$G,J15)&""),0)=IFERROR(--(INDEX('Reguler Class Availability'!$F:$F,J15)&""),0),"Penuh",IF(IFERROR(--(INDEX('Reguler Class Availability'!$G:$G,J15)&""),0)=0,IF(INDEX('Reguler Class Availability'!$B:$B,J15)&""="","Kosong","Belum terisi"),IF(IFERROR(--(INDEX('Reguler Class Availability'!$G:$G,J15)&""),0)/IFERROR(--(INDEX('Reguler Class Availability'!$F:$F,J15)&""),0)>=0.6,"Tinggi","Sebagian")))))) -> Tidak dibuka | S15: =IF(K15="","",IF(AND(IFERROR(--(INDEX('Reguler Class Availability'!$F:$F,K15)&""),0)=0,IFERROR(--(INDEX('Reguler Class Availability'!$G:$G,K15)&""),0)=0),IF(OR(INDEX('Reguler Class Availability'!$B:$B,K15)&""<>"",INDEX('Reguler Class Availability'!$I:$I,K15)&""<>""),"Tutup","Tidak dibuka"),IF(IFERROR(--(INDEX('Reguler Class Availability'!$G:$G,K15)&""),0)>IFERROR(--(INDEX('Reguler Class Availability'!$F:$F,K15)&""),0),"Lebih",IF(IFERROR(--(INDEX('Reguler Class Availability'!$G:$G,K15)&""),0)=IFERROR(--(INDEX('Reguler Class Availability'!$F:$F,K15)&""),0),"Penuh",IF(IFERROR(--(INDEX('Reguler Class Availability'!$G:$G,K15)&""),0)=0,IF(INDEX('Reguler Class Availability'!$B:$B,K15)&""="","Kosong","Belum terisi"),IF(IFERROR(--(INDEX('Reguler Class Availability'!$G:$G,K15)&""),0)/IFERROR(--(INDEX('Reguler Class Availability'!$F:$F,K15)&""),0)>=0.6,"Tinggi","Sebagian")))))) -> Tidak dibuka | T15: =IF(L15="","",IF(AND(IFERROR(--(INDEX('Reguler Class Availability'!$F:$F,L15)&""),0)=0,IFERROR(--(INDEX('Reguler Class Availability'!$G:$G,L15)&""),0)=0),IF(OR(INDEX('Reguler Class Availability'!$B:$B,L15)&""<>"",INDEX('Reguler Class Availability'!$I:$I,L15)&""<>""),"Tutup","Tidak dibuka"),IF(IFERROR(--(INDEX('Reguler Class Availability'!$G:$G,L15)&""),0)>IFERROR(--(INDEX('Reguler Class Availability'!$F:$F,L15)&""),0),"Lebih",IF(IFERROR(--(INDEX('Reguler Class Availability'!$G:$G,L15)&""),0)=IFERROR(--(INDEX('Reguler Class Availability'!$F:$F,L15)&""),0),"Penuh",IF(IFERROR(--(INDEX('Reguler Class Availability'!$G:$G,L15)&""),0)=0,IF(INDEX('Reguler Class Availability'!$B:$B,L15)&""="","Kosong","Belum terisi"),IF(IFERROR(--(INDEX('Reguler Class Availability'!$G:$G,L15)&""),0)/IFERROR(--(INDEX('Reguler Class Availability'!$F:$F,L15)&""),0)>=0.6,"Tinggi","Sebagian")))))) -> Tidak dibuka | U15: =IF(M15="","",IF(AND(IFERROR(--(INDEX('Reguler Class Availability'!$F:$F,M15)&""),0)=0,IFERROR(--(INDEX('Reguler Class Availability'!$G:$G,M15)&""),0)=0),IF(OR(INDEX('Reguler Class Availability'!$B:$B,M15)&""<>"",INDEX('Reguler Class Availability'!$I:$I,M15)&""<>""),"Tutup","Tidak dibuka"),IF(IFERROR(--(INDEX('Reguler Class Availability'!$G:$G,M15)&""),0)>IFERROR(--(INDEX('Reguler Class Availability'!$F:$F,M15)&""),0),"Lebih",IF(IFERROR(--(INDEX('Reguler Class Availability'!$G:$G,M15)&""),0)=IFERROR(--(INDEX('Reguler Class Availability'!$F:$F,M15)&""),0),"Penuh",IF(IFERROR(--(INDEX('Reguler Class Availability'!$G:$G,M15)&""),0)=0,IF(INDEX('Reguler Class Availability'!$B:$B,M15)&""="","Kosong","Belum terisi"),IF(IFERROR(--(INDEX('Reguler Class Availability'!$G:$G,M15)&""),0)/IFERROR(--(INDEX('Reguler Class Availability'!$F:$F,M15)&""),0)>=0.6,"Tinggi","Sebagian")))))) -> Tidak dibuka | V15: =IF(N15="","",IF(AND(IFERROR(--(INDEX('Reguler Class Availability'!$F:$F,N15)&""),0)=0,IFERROR(--(INDEX('Reguler Class Availability'!$G:$G,N15)&""),0)=0),IF(OR(INDEX('Reguler Class Availability'!$B:$B,N15)&""<>"",INDEX('Reguler Class Availability'!$I:$I,N15)&""<>""),"Tutup","Tidak dibuka"),IF(IFERROR(--(INDEX('Reguler Class Availability'!$G:$G,N15)&""),0)>IFERROR(--(INDEX('Reguler Class Availability'!$F:$F,N15)&""),0),"Lebih",IF(IFERROR(--(INDEX('Reguler Class Availability'!$G:$G,N15)&""),0)=IFERROR(--(INDEX('Reguler Class Availability'!$F:$F,N15)&""),0),"Penuh",IF(IFERROR(--(INDEX('Reguler Class Availability'!$G:$G,N15)&""),0)=0,IF(INDEX('Reguler Class Availability'!$B:$B,N15)&""="","Kosong","Belum terisi"),IF(IFERROR(--(INDEX('Reguler Class Availability'!$G:$G,N15)&""),0)/IFERROR(--(INDEX('Reguler Class Availability'!$F:$F,N15)&""),0)>=0.6,"Tinggi","Sebagian")))))) -> Tidak dibuka | W15: =IF(O15="","",IF(AND(IFERROR(--(INDEX('Reguler Class Availability'!$F:$F,O15)&""),0)=0,IFERROR(--(INDEX('Reguler Class Availability'!$G:$G,O15)&""),0)=0),IF(OR(INDEX('Reguler Class Availability'!$B:$B,O15)&""<>"",INDEX('Reguler Class Availability'!$I:$I,O15)&""<>""),"Tutup","Tidak dibuka"),IF(IFERROR(--(INDEX('Reguler Class Availability'!$G:$G,O15)&""),0)>IFERROR(--(INDEX('Reguler Class Availability'!$F:$F,O15)&""),0),"Lebih",IF(IFERROR(--(INDEX('Reguler Class Availability'!$G:$G,O15)&""),0)=IFERROR(--(INDEX('Reguler Class Availability'!$F:$F,O15)&""),0),"Penuh",IF(IFERROR(--(INDEX('Reguler Class Availability'!$G:$G,O15)&""),0)=0,IF(INDEX('Reguler Class Availability'!$B:$B,O15)&""="","Kosong","Belum terisi"),IF(IFERROR(--(INDEX('Reguler Class Availability'!$G:$G,O15)&""),0)/IFERROR(--(INDEX('Reguler Class Availability'!$F:$F,O15)&""),0)>=0.6,"Tinggi","Sebagian")))))) -> Tidak dibuka | X15: =IF(P15="","",IF(AND(IFERROR(--(INDEX('Reguler Class Availability'!$F:$F,P15)&""),0)=0,IFERROR(--(INDEX('Reguler Class Availability'!$G:$G,P15)&""),0)=0),IF(OR(INDEX('Reguler Class Availability'!$B:$B,P15)&""<>"",INDEX('Reguler Class Availability'!$I:$I,P15)&""<>""),"Tutup","Tidak dibuka"),IF(IFERROR(--(INDEX('Reguler Class Availability'!$G:$G,P15)&""),0)>IFERROR(--(INDEX('Reguler Class Availability'!$F:$F,P15)&""),0),"Lebih",IF(IFERROR(--(INDEX('Reguler Class Availability'!$G:$G,P15)&""),0)=IFERROR(--(INDEX('Reguler Class Availability'!$F:$F,P15)&""),0),"Penuh",IF(IFERROR(--(INDEX('Reguler Class Availability'!$G:$G,P15)&""),0)=0,IF(INDEX('Reguler Class Availability'!$B:$B,P15)&""="","Kosong","Belum terisi"),IF(IFERROR(--(INDEX('Reguler Class Availability'!$G:$G,P15)&""),0)/IFERROR(--(INDEX('Reguler Class Availability'!$F:$F,P15)&""),0)>=0.6,"Tinggi","Sebagian")))))) -> Tidak dibuka | Z15: 09:15 | AA15: =IF(COUNTIFS('Reguler Class Availability'!$L:$L,$B$4&"|- Lane 1 - *|"&Z15)>0,1,0) -> 0 | AB15: =AA15+AB14 -> 3
A16: =IFERROR(INDEX($Z$2:$Z$61,MATCH(3,$AB$2:$AB$61,0)),"") -> 09:00 | B16: =IF(J16="","",IF(R16="Tidak dibuka","–",IF(INDEX('Reguler Class Availability'!$B:$B,J16)&""="","Kosong",PROPER(INDEX('Reguler Class Availability'!$B:$B,J16)&""))&" "&IFERROR(--(INDEX('Reguler Class Availability'!$G:$G,J16)&""),0)&"/"&IFERROR(--(INDEX('Reguler Class Availability'!$F:$F,J16)&""),0)&IF(IFERROR(--(INDEX('Reguler Class Availability'!$F:$F,J16)&""),0)>0," ("&TEXT(IFERROR(--(INDEX('Reguler Class Availability'!$G:$G,J16)&""),0)/IFERROR(--(INDEX('Reguler Class Availability'!$F:$F,J16)&""),0),"0%")&")","")&CHAR(10)&IF(INDEX('Reguler Class Availability'!$I:$I,J16)&""="","coach: –",PROPER(INDEX('Reguler Class Availability'!$I:$I,J16)&""))&IF(INDEX('Reguler Class Availability'!$J:$J,J16)&""="","",CHAR(10)&"asst: "&PROPER(INDEX('Reguler Class Availability'!$J:$J,J16)&"")))) -> Kosong 0/5 (0%) coach: – | C16: =IF(K16="","",IF(S16="Tidak dibuka","–",IF(INDEX('Reguler Class Availability'!$B:$B,K16)&""="","Kosong",PROPER(INDEX('Reguler Class Availability'!$B:$B,K16)&""))&" "&IFERROR(--(INDEX('Reguler Class Availability'!$G:$G,K16)&""),0)&"/"&IFERROR(--(INDEX('Reguler Class Availability'!$F:$F,K16)&""),0)&IF(IFERROR(--(INDEX('Reguler Class Availability'!$F:$F,K16)&""),0)>0," ("&TEXT(IFERROR(--(INDEX('Reguler Class Availability'!$G:$G,K16)&""),0)/IFERROR(--(INDEX('Reguler Class Availability'!$F:$F,K16)&""),0),"0%")&")","")&CHAR(10)&IF(INDEX('Reguler Class Availability'!$I:$I,K16)&""="","coach: –",PROPER(INDEX('Reguler Class Availability'!$I:$I,K16)&""))&IF(INDEX('Reguler Class Availability'!$J:$J,K16)&""="","",CHAR(10)&"asst: "&PROPER(INDEX('Reguler Class Availability'!$J:$J,K16)&"")))) -> Kosong 0/5 (0%) coach: – | D16: =IF(L16="","",IF(T16="Tidak dibuka","–",IF(INDEX('Reguler Class Availability'!$B:$B,L16)&""="","Kosong",PROPER(INDEX('Reguler Class Availability'!$B:$B,L16)&""))&" "&IFERROR(--(INDEX('Reguler Class Availability'!$G:$G,L16)&""),0)&"/"&IFERROR(--(INDEX('Reguler Class Availability'!$F:$F,L16)&""),0)&IF(IFERROR(--(INDEX('Reguler Class Availability'!$F:$F,L16)&""),0)>0," ("&TEXT(IFERROR(--(INDEX('Reguler Class Availability'!$G:$G,L16)&""),0)/IFERROR(--(INDEX('Reguler Class Availability'!$F:$F,L16)&""),0),"0%")&")","")&CHAR(10)&IF(INDEX('Reguler Class Availability'!$I:$I,L16)&""="","coach: –",PROPER(INDEX('Reguler Class Availability'!$I:$I,L16)&""))&IF(INDEX('Reguler Class Availability'!$J:$J,L16)&""="","",CHAR(10)&"asst: "&PROPER(INDEX('Reguler Class Availability'!$J:$J,L16)&"")))) -> Baby 5/5 (100%) Nuky | E16: =IF(M16="","",IF(U16="Tidak dibuka","–",IF(INDEX('Reguler Class Availability'!$B:$B,M16)&""="","Kosong",PROPER(INDEX('Reguler Class Availability'!$B:$B,M16)&""))&" "&IFERROR(--(INDEX('Reguler Class Availability'!$G:$G,M16)&""),0)&"/"&IFERROR(--(INDEX('Reguler Class Availability'!$F:$F,M16)&""),0)&IF(IFERROR(--(INDEX('Reguler Class Availability'!$F:$F,M16)&""),0)>0," ("&TEXT(IFERROR(--(INDEX('Reguler Class Availability'!$G:$G,M16)&""),0)/IFERROR(--(INDEX('Reguler Class Availability'!$F:$F,M16)&""),0),"0%")&")","")&CHAR(10)&IF(INDEX('Reguler Class Availability'!$I:$I,M16)&""="","coach: –",PROPER(INDEX('Reguler Class Availability'!$I:$I,M16)&""))&IF(INDEX('Reguler Class Availability'!$J:$J,M16)&""="","",CHAR(10)&"asst: "&PROPER(INDEX('Reguler Class Availability'!$J:$J,M16)&"")))) -> Kosong 0/5 (0%) coach: – | F16: =IF(N16="","",IF(V16="Tidak dibuka","–",IF(INDEX('Reguler Class Availability'!$B:$B,N16)&""="","Kosong",PROPER(INDEX('Reguler Class Availability'!$B:$B,N16)&""))&" "&IFERROR(--(INDEX('Reguler Class Availability'!$G:$G,N16)&""),0)&"/"&IFERROR(--(INDEX('Reguler Class Availability'!$F:$F,N16)&""),0)&IF(IFERROR(--(INDEX('Reguler Class Availability'!$F:$F,N16)&""),0)>0," ("&TEXT(IFERROR(--(INDEX('Reguler Class Availability'!$G:$G,N16)&""),0)/IFERROR(--(INDEX('Reguler Class Availability'!$F:$F,N16)&""),0),"0%")&")","")&CHAR(10)&IF(INDEX('Reguler Class Availability'!$I:$I,N16)&""="","coach: –",PROPER(INDEX('Reguler Class Availability'!$I:$I,N16)&""))&IF(INDEX('Reguler Class Availability'!$J:$J,N16)&""="","",CHAR(10)&"asst: "&PROPER(INDEX('Reguler Class Availability'!$J:$J,N16)&"")))) -> Baby 5/5 (100%) Surya | G16: =IF(O16="","",IF(W16="Tidak dibuka","–",IF(INDEX('Reguler Class Availability'!$B:$B,O16)&""="","Kosong",PROPER(INDEX('Reguler Class Availability'!$B:$B,O16)&""))&" "&IFERROR(--(INDEX('Reguler Class Availability'!$G:$G,O16)&""),0)&"/"&IFERROR(--(INDEX('Reguler Class Availability'!$F:$F,O16)&""),0)&IF(IFERROR(--(INDEX('Reguler Class Availability'!$F:$F,O16)&""),0)>0," ("&TEXT(IFERROR(--(INDEX('Reguler Class Availability'!$G:$G,O16)&""),0)/IFERROR(--(INDEX('Reguler Class Availability'!$F:$F,O16)&""),0),"0%")&")","")&CHAR(10)&IF(INDEX('Reguler Class Availability'!$I:$I,O16)&""="","coach: –",PROPER(INDEX('Reguler Class Availability'!$I:$I,O16)&""))&IF(INDEX('Reguler Class Availability'!$J:$J,O16)&""="","",CHAR(10)&"asst: "&PROPER(INDEX('Reguler Class Availability'!$J:$J,O16)&"")))) -> Baby 5/5 (100%) Eka | H16: =IF(P16="","",IF(X16="Tidak dibuka","–",IF(INDEX('Reguler Class Availability'!$B:$B,P16)&""="","Kosong",PROPER(INDEX('Reguler Class Availability'!$B:$B,P16)&""))&" "&IFERROR(--(INDEX('Reguler Class Availability'!$G:$G,P16)&""),0)&"/"&IFERROR(--(INDEX('Reguler Class Availability'!$F:$F,P16)&""),0)&IF(IFERROR(--(INDEX('Reguler Class Availability'!$F:$F,P16)&""),0)>0," ("&TEXT(IFERROR(--(INDEX('Reguler Class Availability'!$G:$G,P16)&""),0)/IFERROR(--(INDEX('Reguler Class Availability'!$F:$F,P16)&""),0),"0%")&")","")&CHAR(10)&IF(INDEX('Reguler Class Availability'!$I:$I,P16)&""="","coach: –",PROPER(INDEX('Reguler Class Availability'!$I:$I,P16)&""))&IF(INDEX('Reguler Class Availability'!$J:$J,P16)&""="","",CHAR(10)&"asst: "&PROPER(INDEX('Reguler Class Availability'!$J:$J,P16)&"")))) -> Baby 5/5 (100%) Rischa | J16: =IF($A16="","",IFERROR(MATCH($B$4&"|- Lane 1 - "&B$13&"|"&$A16,'Reguler Class Availability'!$L:$L,0),"")) -> 3 | K16: =IF($A16="","",IFERROR(MATCH($B$4&"|- Lane 1 - "&C$13&"|"&$A16,'Reguler Class Availability'!$L:$L,0),"")) -> 15 | L16: =IF($A16="","",IFERROR(MATCH($B$4&"|- Lane 1 - "&D$13&"|"&$A16,'Reguler Class Availability'!$L:$L,0),"")) -> 27 | M16: =IF($A16="","",IFERROR(MATCH($B$4&"|- Lane 1 - "&E$13&"|"&$A16,'Reguler Class Availability'!$L:$L,0),"")) -> 39 | N16: =IF($A16="","",IFERROR(MATCH($B$4&"|- Lane 1 - "&F$13&"|"&$A16,'Reguler Class Availability'!$L:$L,0),"")) -> 51 | O16: =IF($A16="","",IFERROR(MATCH($B$4&"|- Lane 1 - "&G$13&"|"&$A16,'Reguler Class Availability'!$L:$L,0),"")) -> 63 | P16: =IF($A16="","",IFERROR(MATCH($B$4&"|- Lane 1 - "&H$13&"|"&$A16,'Reguler Class Availability'!$L:$L,0),"")) -> 75 | R16: =IF(J16="","",IF(AND(IFERROR(--(INDEX('Reguler Class Availability'!$F:$F,J16)&""),0)=0,IFERROR(--(INDEX('Reguler Class Availability'!$G:$G,J16)&""),0)=0),IF(OR(INDEX('Reguler Class Availability'!$B:$B,J16)&""<>"",INDEX('Reguler Class Availability'!$I:$I,J16)&""<>""),"Tutup","Tidak dibuka"),IF(IFERROR(--(INDEX('Reguler Class Availability'!$G:$G,J16)&""),0)>IFERROR(--(INDEX('Reguler Class Availability'!$F:$F,J16)&""),0),"Lebih",IF(IFERROR(--(INDEX('Reguler Class Availability'!$G:$G,J16)&""),0)=IFERROR(--(INDEX('Reguler Class Availability'!$F:$F,J16)&""),0),"Penuh",IF(IFERROR(--(INDEX('Reguler Class Availability'!$G:$G,J16)&""),0)=0,IF(INDEX('Reguler Class Availability'!$B:$B,J16)&""="","Kosong","Belum terisi"),IF(IFERROR(--(INDEX('Reguler Class Availability'!$G:$G,J16)&""),0)/IFERROR(--(INDEX('Reguler Class Availability'!$F:$F,J16)&""),0)>=0.6,"Tinggi","Sebagian")))))) -> Kosong | S16: =IF(K16="","",IF(AND(IFERROR(--(INDEX('Reguler Class Availability'!$F:$F,K16)&""),0)=0,IFERROR(--(INDEX('Reguler Class Availability'!$G:$G,K16)&""),0)=0),IF(OR(INDEX('Reguler Class Availability'!$B:$B,K16)&""<>"",INDEX('Reguler Class Availability'!$I:$I,K16)&""<>""),"Tutup","Tidak dibuka"),IF(IFERROR(--(INDEX('Reguler Class Availability'!$G:$G,K16)&""),0)>IFERROR(--(INDEX('Reguler Class Availability'!$F:$F,K16)&""),0),"Lebih",IF(IFERROR(--(INDEX('Reguler Class Availability'!$G:$G,K16)&""),0)=IFERROR(--(INDEX('Reguler Class Availability'!$F:$F,K16)&""),0),"Penuh",IF(IFERROR(--(INDEX('Reguler Class Availability'!$G:$G,K16)&""),0)=0,IF(INDEX('Reguler Class Availability'!$B:$B,K16)&""="","Kosong","Belum terisi"),IF(IFERROR(--(INDEX('Reguler Class Availability'!$G:$G,K16)&""),0)/IFERROR(--(INDEX('Reguler Class Availability'!$F:$F,K16)&""),0)>=0.6,"Tinggi","Sebagian")))))) -> Kosong | T16: =IF(L16="","",IF(AND(IFERROR(--(INDEX('Reguler Class Availability'!$F:$F,L16)&""),0)=0,IFERROR(--(INDEX('Reguler Class Availability'!$G:$G,L16)&""),0)=0),IF(OR(INDEX('Reguler Class Availability'!$B:$B,L16)&""<>"",INDEX('Reguler Class Availability'!$I:$I,L16)&""<>""),"Tutup","Tidak dibuka"),IF(IFERROR(--(INDEX('Reguler Class Availability'!$G:$G,L16)&""),0)>IFERROR(--(INDEX('Reguler Class Availability'!$F:$F,L16)&""),0),"Lebih",IF(IFERROR(--(INDEX('Reguler Class Availability'!$G:$G,L16)&""),0)=IFERROR(--(INDEX('Reguler Class Availability'!$F:$F,L16)&""),0),"Penuh",IF(IFERROR(--(INDEX('Reguler Class Availability'!$G:$G,L16)&""),0)=0,IF(INDEX('Reguler Class Availability'!$B:$B,L16)&""="","Kosong","Belum terisi"),IF(IFERROR(--(INDEX('Reguler Class Availability'!$G:$G,L16)&""),0)/IFERROR(--(INDEX('Reguler Class Availability'!$F:$F,L16)&""),0)>=0.6,"Tinggi","Sebagian")))))) -> Penuh | U16: =IF(M16="","",IF(AND(IFERROR(--(INDEX('Reguler Class Availability'!$F:$F,M16)&""),0)=0,IFERROR(--(INDEX('Reguler Class Availability'!$G:$G,M16)&""),0)=0),IF(OR(INDEX('Reguler Class Availability'!$B:$B,M16)&""<>"",INDEX('Reguler Class Availability'!$I:$I,M16)&""<>""),"Tutup","Tidak dibuka"),IF(IFERROR(--(INDEX('Reguler Class Availability'!$G:$G,M16)&""),0)>IFERROR(--(INDEX('Reguler Class Availability'!$F:$F,M16)&""),0),"Lebih",IF(IFERROR(--(INDEX('Reguler Class Availability'!$G:$G,M16)&""),0)=IFERROR(--(INDEX('Reguler Class Availability'!$F:$F,M16)&""),0),"Penuh",IF(IFERROR(--(INDEX('Reguler Class Availability'!$G:$G,M16)&""),0)=0,IF(INDEX('Reguler Class Availability'!$B:$B,M16)&""="","Kosong","Belum terisi"),IF(IFERROR(--(INDEX('Reguler Class Availability'!$G:$G,M16)&""),0)/IFERROR(--(INDEX('Reguler Class Availability'!$F:$F,M16)&""),0)>=0.6,"Tinggi","Sebagian")))))) -> Kosong | V16: =IF(N16="","",IF(AND(IFERROR(--(INDEX('Reguler Class Availability'!$F:$F,N16)&""),0)=0,IFERROR(--(INDEX('Reguler Class Availability'!$G:$G,N16)&""),0)=0),IF(OR(INDEX('Reguler Class Availability'!$B:$B,N16)&""<>"",INDEX('Reguler Class Availability'!$I:$I,N16)&""<>""),"Tutup","Tidak dibuka"),IF(IFERROR(--(INDEX('Reguler Class Availability'!$G:$G,N16)&""),0)>IFERROR(--(INDEX('Reguler Class Availability'!$F:$F,N16)&""),0),"Lebih",IF(IFERROR(--(INDEX('Reguler Class Availability'!$G:$G,N16)&""),0)=IFERROR(--(INDEX('Reguler Class Availability'!$F:$F,N16)&""),0),"Penuh",IF(IFERROR(--(INDEX('Reguler Class Availability'!$G:$G,N16)&""),0)=0,IF(INDEX('Reguler Class Availability'!$B:$B,N16)&""="","Kosong","Belum terisi"),IF(IFERROR(--(INDEX('Reguler Class Availability'!$G:$G,N16)&""),0)/IFERROR(--(INDEX('Reguler Class Availability'!$F:$F,N16)&""),0)>=0.6,"Tinggi","Sebagian")))))) -> Penuh | W16: =IF(O16="","",IF(AND(IFERROR(--(INDEX('Reguler Class Availability'!$F:$F,O16)&""),0)=0,IFERROR(--(INDEX('Reguler Class Availability'!$G:$G,O16)&""),0)=0),IF(OR(INDEX('Reguler Class Availability'!$B:$B,O16)&""<>"",INDEX('Reguler Class Availability'!$I:$I,O16)&""<>""),"Tutup","Tidak dibuka"),IF(IFERROR(--(INDEX('Reguler Class Availability'!$G:$G,O16)&""),0)>IFERROR(--(INDEX('Reguler Class Availability'!$F:$F,O16)&""),0),"Lebih",IF(IFERROR(--(INDEX('Reguler Class Availability'!$G:$G,O16)&""),0)=IFERROR(--(INDEX('Reguler Class Availability'!$F:$F,O16)&""),0),"Penuh",IF(IFERROR(--(INDEX('Reguler Class Availability'!$G:$G,O16)&""),0)=0,IF(INDEX('Reguler Class Availability'!$B:$B,O16)&""="","Kosong","Belum terisi"),IF(IFERROR(--(INDEX('Reguler Class Availability'!$G:$G,O16)&""),0)/IFERROR(--(INDEX('Reguler Class Availability'!$F:$F,O16)&""),0)>=0.6,"Tinggi","Sebagian")))))) -> Penuh | X16: =IF(P16="","",IF(AND(IFERROR(--(INDEX('Reguler Class Availability'!$F:$F,P16)&""),0)=0,IFERROR(--(INDEX('Reguler Class Availability'!$G:$G,P16)&""),0)=0),IF(OR(INDEX('Reguler Class Availability'!$B:$B,P16)&""<>"",INDEX('Reguler Class Availability'!$I:$I,P16)&""<>""),"Tutup","Tidak dibuka"),IF(IFERROR(--(INDEX('Reguler Class Availability'!$G:$G,P16)&""),0)>IFERROR(--(INDEX('Reguler Class Availability'!$F:$F,P16)&""),0),"Lebih",IF(IFERROR(--(INDEX('Reguler Class Availability'!$G:$G,P16)&""),0)=IFERROR(--(INDEX('Reguler Class Availability'!$F:$F,P16)&""),0),"Penuh",IF(IFERROR(--(INDEX('Reguler Class Availability'!$G:$G,P16)&""),0)=0,IF(INDEX('Reguler Class Availability'!$B:$B,P16)&""="","Kosong","Belum terisi"),IF(IFERROR(--(INDEX('Reguler Class Availability'!$G:$G,P16)&""),0)/IFERROR(--(INDEX('Reguler Class Availability'!$F:$F,P16)&""),0)>=0.6,"Tinggi","Sebagian")))))) -> Penuh | Z16: 09:30 | AA16: =IF(COUNTIFS('Reguler Class Availability'!$L:$L,$B$4&"|- Lane 1 - *|"&Z16)>0,1,0) -> 0 | AB16: =AA16+AB15 -> 3
A17: =IFERROR(INDEX($Z$2:$Z$61,MATCH(4,$AB$2:$AB$61,0)),"") -> 09:45 | B17: =IF(J17="","",IF(R17="Tidak dibuka","–",IF(INDEX('Reguler Class Availability'!$B:$B,J17)&""="","Kosong",PROPER(INDEX('Reguler Class Availability'!$B:$B,J17)&""))&" "&IFERROR(--(INDEX('Reguler Class Availability'!$G:$G,J17)&""),0)&"/"&IFERROR(--(INDEX('Reguler Class Availability'!$F:$F,J17)&""),0)&IF(IFERROR(--(INDEX('Reguler Class Availability'!$F:$F,J17)&""),0)>0," ("&TEXT(IFERROR(--(INDEX('Reguler Class Availability'!$G:$G,J17)&""),0)/IFERROR(--(INDEX('Reguler Class Availability'!$F:$F,J17)&""),0),"0%")&")","")&CHAR(10)&IF(INDEX('Reguler Class Availability'!$I:$I,J17)&""="","coach: –",PROPER(INDEX('Reguler Class Availability'!$I:$I,J17)&""))&IF(INDEX('Reguler Class Availability'!$J:$J,J17)&""="","",CHAR(10)&"asst: "&PROPER(INDEX('Reguler Class Availability'!$J:$J,J17)&"")))) -> Kosong 0/5 (0%) coach: – | C17: =IF(K17="","",IF(S17="Tidak dibuka","–",IF(INDEX('Reguler Class Availability'!$B:$B,K17)&""="","Kosong",PROPER(INDEX('Reguler Class Availability'!$B:$B,K17)&""))&" "&IFERROR(--(INDEX('Reguler Class Availability'!$G:$G,K17)&""),0)&"/"&IFERROR(--(INDEX('Reguler Class Availability'!$F:$F,K17)&""),0)&IF(IFERROR(--(INDEX('Reguler Class Availability'!$F:$F,K17)&""),0)>0," ("&TEXT(IFERROR(--(INDEX('Reguler Class Availability'!$G:$G,K17)&""),0)/IFERROR(--(INDEX('Reguler Class Availability'!$F:$F,K17)&""),0),"0%")&")","")&CHAR(10)&IF(INDEX('Reguler Class Availability'!$I:$I,K17)&""="","coach: –",PROPER(INDEX('Reguler Class Availability'!$I:$I,K17)&""))&IF(INDEX('Reguler Class Availability'!$J:$J,K17)&""="","",CHAR(10)&"asst: "&PROPER(INDEX('Reguler Class Availability'!$J:$J,K17)&"")))) -> Kosong 0/5 (0%) coach: – | D17: =IF(L17="","",IF(T17="Tidak dibuka","–",IF(INDEX('Reguler Class Availability'!$B:$B,L17)&""="","Kosong",PROPER(INDEX('Reguler Class Availability'!$B:$B,L17)&""))&" "&IFERROR(--(INDEX('Reguler Class Availability'!$G:$G,L17)&""),0)&"/"&IFERROR(--(INDEX('Reguler Class Availability'!$F:$F,L17)&""),0)&IF(IFERROR(--(INDEX('Reguler Class Availability'!$F:$F,L17)&""),0)>0," ("&TEXT(IFERROR(--(INDEX('Reguler Class Availability'!$G:$G,L17)&""),0)/IFERROR(--(INDEX('Reguler Class Availability'!$F:$F,L17)&""),0),"0%")&")","")&CHAR(10)&IF(INDEX('Reguler Class Availability'!$I:$I,L17)&""="","coach: –",PROPER(INDEX('Reguler Class Availability'!$I:$I,L17)&""))&IF(INDEX('Reguler Class Availability'!$J:$J,L17)&""="","",CHAR(10)&"asst: "&PROPER(INDEX('Reguler Class Availability'!$J:$J,L17)&"")))) -> Kosong 0/5 (0%) coach: – | E17: =IF(M17="","",IF(U17="Tidak dibuka","–",IF(INDEX('Reguler Class Availability'!$B:$B,M17)&""="","Kosong",PROPER(INDEX('Reguler Class Availability'!$B:$B,M17)&""))&" "&IFERROR(--(INDEX('Reguler Class Availability'!$G:$G,M17)&""),0)&"/"&IFERROR(--(INDEX('Reguler Class Availability'!$F:$F,M17)&""),0)&IF(IFERROR(--(INDEX('Reguler Class Availability'!$F:$F,M17)&""),0)>0," ("&TEXT(IFERROR(--(INDEX('Reguler Class Availability'!$G:$G,M17)&""),0)/IFERROR(--(INDEX('Reguler Class Availability'!$F:$F,M17)&""),0),"0%")&")","")&CHAR(10)&IF(INDEX('Reguler Class Availability'!$I:$I,M17)&""="","coach: –",PROPER(INDEX('Reguler Class Availability'!$I:$I,M17)&""))&IF(INDEX('Reguler Class Availability'!$J:$J,M17)&""="","",CHAR(10)&"asst: "&PROPER(INDEX('Reguler Class Availability'!$J:$J,M17)&"")))) -> Kosong 0/5 (0%) coach: – | F17: =IF(N17="","",IF(V17="Tidak dibuka","–",IF(INDEX('Reguler Class Availability'!$B:$B,N17)&""="","Kosong",PROPER(INDEX('Reguler Class Availability'!$B:$B,N17)&""))&" "&IFERROR(--(INDEX('Reguler Class Availability'!$G:$G,N17)&""),0)&"/"&IFERROR(--(INDEX('Reguler Class Availability'!$F:$F,N17)&""),0)&IF(IFERROR(--(INDEX('Reguler Class Availability'!$F:$F,N17)&""),0)>0," ("&TEXT(IFERROR(--(INDEX('Reguler Class Availability'!$G:$G,N17)&""),0)/IFERROR(--(INDEX('Reguler Class Availability'!$F:$F,N17)&""),0),"0%")&")","")&CHAR(10)&IF(INDEX('Reguler Class Availability'!$I:$I,N17)&""="","coach: –",PROPER(INDEX('Reguler Class Availability'!$I:$I,N17)&""))&IF(INDEX('Reguler Class Availability'!$J:$J,N17)&""="","",CHAR(10)&"asst: "&PROPER(INDEX('Reguler Class Availability'!$J:$J,N17)&"")))) -> Kosong 0/5 (0%) coach: – | G17: =IF(O17="","",IF(W17="Tidak dibuka","–",IF(INDEX('Reguler Class Availability'!$B:$B,O17)&""="","Kosong",PROPER(INDEX('Reguler Class Availability'!$B:$B,O17)&""))&" "&IFERROR(--(INDEX('Reguler Class Availability'!$G:$G,O17)&""),0)&"/"&IFERROR(--(INDEX('Reguler Class Availability'!$F:$F,O17)&""),0)&IF(IFERROR(--(INDEX('Reguler Class Availability'!$F:$F,O17)&""),0)>0," ("&TEXT(IFERROR(--(INDEX('Reguler Class Availability'!$G:$G,O17)&""),0)/IFERROR(--(INDEX('Reguler Class Availability'!$F:$F,O17)&""),0),"0%")&")","")&CHAR(10)&IF(INDEX('Reguler Class Availability'!$I:$I,O17)&""="","coach: –",PROPER(INDEX('Reguler Class Availability'!$I:$I,O17)&""))&IF(INDEX('Reguler Class Availability'!$J:$J,O17)&""="","",CHAR(10)&"asst: "&PROPER(INDEX('Reguler Class Availability'!$J:$J,O17)&"")))) -> Baby 5/5 (100%) Rischa | H17: =IF(P17="","",IF(X17="Tidak dibuka","–",IF(INDEX('Reguler Class Availability'!$B:$B,P17)&""="","Kosong",PROPER(INDEX('Reguler Class Availability'!$B:$B,P17)&""))&" "&IFERROR(--(INDEX('Reguler Class Availability'!$G:$G,P17)&""),0)&"/"&IFERROR(--(INDEX('Reguler Class Availability'!$F:$F,P17)&""),0)&IF(IFERROR(--(INDEX('Reguler Class Availability'!$F:$F,P17)&""),0)>0," ("&TEXT(IFERROR(--(INDEX('Reguler Class Availability'!$G:$G,P17)&""),0)/IFERROR(--(INDEX('Reguler Class Availability'!$F:$F,P17)&""),0),"0%")&")","")&CHAR(10)&IF(INDEX('Reguler Class Availability'!$I:$I,P17)&""="","coach: –",PROPER(INDEX('Reguler Class Availability'!$I:$I,P17)&""))&IF(INDEX('Reguler Class Availability'!$J:$J,P17)&""="","",CHAR(10)&"asst: "&PROPER(INDEX('Reguler Class Availability'!$J:$J,P17)&"")))) -> Baby 5/5 (100%) Zidane | J17: =IF($A17="","",IFERROR(MATCH($B$4&"|- Lane 1 - "&B$13&"|"&$A17,'Reguler Class Availability'!$L:$L,0),"")) -> 4 | K17: =IF($A17="","",IFERROR(MATCH($B$4&"|- Lane 1 - "&C$13&"|"&$A17,'Reguler Class Availability'!$L:$L,0),"")) -> 16 | L17: =IF($A17="","",IFERROR(MATCH($B$4&"|- Lane 1 - "&D$13&"|"&$A17,'Reguler Class Availability'!$L:$L,0),"")) -> 28 | M17: =IF($A17="","",IFERROR(MATCH($B$4&"|- Lane 1 - "&E$13&"|"&$A17,'Reguler Class Availability'!$L:$L,0),"")) -> 40 | N17: =IF($A17="","",IFERROR(MATCH($B$4&"|- Lane 1 - "&F$13&"|"&$A17,'Reguler Class Availability'!$L:$L,0),"")) -> 52 | O17: =IF($A17="","",IFERROR(MATCH($B$4&"|- Lane 1 - "&G$13&"|"&$A17,'Reguler Class Availability'!$L:$L,0),"")) -> 64 | P17: =IF($A17="","",IFERROR(MATCH($B$4&"|- Lane 1 - "&H$13&"|"&$A17,'Reguler Class Availability'!$L:$L,0),"")) -> 76 | R17: =IF(J17="","",IF(AND(IFERROR(--(INDEX('Reguler Class Availability'!$F:$F,J17)&""),0)=0,IFERROR(--(INDEX('Reguler Class Availability'!$G:$G,J17)&""),0)=0),IF(OR(INDEX('Reguler Class Availability'!$B:$B,J17)&""<>"",INDEX('Reguler Class Availability'!$I:$I,J17)&""<>""),"Tutup","Tidak dibuka"),IF(IFERROR(--(INDEX('Reguler Class Availability'!$G:$G,J17)&""),0)>IFERROR(--(INDEX('Reguler Class Availability'!$F:$F,J17)&""),0),"Lebih",IF(IFERROR(--(INDEX('Reguler Class Availability'!$G:$G,J17)&""),0)=IFERROR(--(INDEX('Reguler Class Availability'!$F:$F,J17)&""),0),"Penuh",IF(IFERROR(--(INDEX('Reguler Class Availability'!$G:$G,J17)&""),0)=0,IF(INDEX('Reguler Class Availability'!$B:$B,J17)&""="","Kosong","Belum terisi"),IF(IFERROR(--(INDEX('Reguler Class Availability'!$G:$G,J17)&""),0)/IFERROR(--(INDEX('Reguler Class Availability'!$F:$F,J17)&""),0)>=0.6,"Tinggi","Sebagian")))))) -> Kosong | S17: =IF(K17="","",IF(AND(IFERROR(--(INDEX('Reguler Class Availability'!$F:$F,K17)&""),0)=0,IFERROR(--(INDEX('Reguler Class Availability'!$G:$G,K17)&""),0)=0),IF(OR(INDEX('Reguler Class Availability'!$B:$B,K17)&""<>"",INDEX('Reguler Class Availability'!$I:$I,K17)&""<>""),"Tutup","Tidak dibuka"),IF(IFERROR(--(INDEX('Reguler Class Availability'!$G:$G,K17)&""),0)>IFERROR(--(INDEX('Reguler Class Availability'!$F:$F,K17)&""),0),"Lebih",IF(IFERROR(--(INDEX('Reguler Class Availability'!$G:$G,K17)&""),0)=IFERROR(--(INDEX('Reguler Class Availability'!$F:$F,K17)&""),0),"Penuh",IF(IFERROR(--(INDEX('Reguler Class Availability'!$G:$G,K17)&""),0)=0,IF(INDEX('Reguler Class Availability'!$B:$B,K17)&""="","Kosong","Belum terisi"),IF(IFERROR(--(INDEX('Reguler Class Availability'!$G:$G,K17)&""),0)/IFERROR(--(INDEX('Reguler Class Availability'!$F:$F,K17)&""),0)>=0.6,"Tinggi","Sebagian")))))) -> Kosong | T17: =IF(L17="","",IF(AND(IFERROR(--(INDEX('Reguler Class Availability'!$F:$F,L17)&""),0)=0,IFERROR(--(INDEX('Reguler Class Availability'!$G:$G,L17)&""),0)=0),IF(OR(INDEX('Reguler Class Availability'!$B:$B,L17)&""<>"",INDEX('Reguler Class Availability'!$I:$I,L17)&""<>""),"Tutup","Tidak dibuka"),IF(IFERROR(--(INDEX('Reguler Class Availability'!$G:$G,L17)&""),0)>IFERROR(--(INDEX('Reguler Class Availability'!$F:$F,L17)&""),0),"Lebih",IF(IFERROR(--(INDEX('Reguler Class Availability'!$G:$G,L17)&""),0)=IFERROR(--(INDEX('Reguler Class Availability'!$F:$F,L17)&""),0),"Penuh",IF(IFERROR(--(INDEX('Reguler Class Availability'!$G:$G,L17)&""),0)=0,IF(INDEX('Reguler Class Availability'!$B:$B,L17)&""="","Kosong","Belum terisi"),IF(IFERROR(--(INDEX('Reguler Class Availability'!$G:$G,L17)&""),0)/IFERROR(--(INDEX('Reguler Class Availability'!$F:$F,L17)&""),0)>=0.6,"Tinggi","Sebagian")))))) -> Kosong | U17: =IF(M17="","",IF(AND(IFERROR(--(INDEX('Reguler Class Availability'!$F:$F,M17)&""),0)=0,IFERROR(--(INDEX('Reguler Class Availability'!$G:$G,M17)&""),0)=0),IF(OR(INDEX('Reguler Class Availability'!$B:$B,M17)&""<>"",INDEX('Reguler Class Availability'!$I:$I,M17)&""<>""),"Tutup","Tidak dibuka"),IF(IFERROR(--(INDEX('Reguler Class Availability'!$G:$G,M17)&""),0)>IFERROR(--(INDEX('Reguler Class Availability'!$F:$F,M17)&""),0),"Lebih",IF(IFERROR(--(INDEX('Reguler Class Availability'!$G:$G,M17)&""),0)=IFERROR(--(INDEX('Reguler Class Availability'!$F:$F,M17)&""),0),"Penuh",IF(IFERROR(--(INDEX('Reguler Class Availability'!$G:$G,M17)&""),0)=0,IF(INDEX('Reguler Class Availability'!$B:$B,M17)&""="","Kosong","Belum terisi"),IF(IFERROR(--(INDEX('Reguler Class Availability'!$G:$G,M17)&""),0)/IFERROR(--(INDEX('Reguler Class Availability'!$F:$F,M17)&""),0)>=0.6,"Tinggi","Sebagian")))))) -> Kosong | V17: =IF(N17="","",IF(AND(IFERROR(--(INDEX('Reguler Class Availability'!$F:$F,N17)&""),0)=0,IFERROR(--(INDEX('Reguler Class Availability'!$G:$G,N17)&""),0)=0),IF(OR(INDEX('Reguler Class Availability'!$B:$B,N17)&""<>"",INDEX('Reguler Class Availability'!$I:$I,N17)&""<>""),"Tutup","Tidak dibuka"),IF(IFERROR(--(INDEX('Reguler Class Availability'!$G:$G,N17)&""),0)>IFERROR(--(INDEX('Reguler Class Availability'!$F:$F,N17)&""),0),"Lebih",IF(IFERROR(--(INDEX('Reguler Class Availability'!$G:$G,N17)&""),0)=IFERROR(--(INDEX('Reguler Class Availability'!$F:$F,N17)&""),0),"Penuh",IF(IFERROR(--(INDEX('Reguler Class Availability'!$G:$G,N17)&""),0)=0,IF(INDEX('Reguler Class Availability'!$B:$B,N17)&""="","Kosong","Belum terisi"),IF(IFERROR(--(INDEX('Reguler Class Availability'!$G:$G,N17)&""),0)/IFERROR(--(INDEX('Reguler Class Availability'!$F:$F,N17)&""),0)>=0.6,"Tinggi","Sebagian")))))) -> Kosong | W17: =IF(O17="","",IF(AND(IFERROR(--(INDEX('Reguler Class Availability'!$F:$F,O17)&""),0)=0,IFERROR(--(INDEX('Reguler Class Availability'!$G:$G,O17)&""),0)=0),IF(OR(INDEX('Reguler Class Availability'!$B:$B,O17)&""<>"",INDEX('Reguler Class Availability'!$I:$I,O17)&""<>""),"Tutup","Tidak dibuka"),IF(IFERROR(--(INDEX('Reguler Class Availability'!$G:$G,O17)&""),0)>IFERROR(--(INDEX('Reguler Class Availability'!$F:$F,O17)&""),0),"Lebih",IF(IFERROR(--(INDEX('Reguler Class Availability'!$G:$G,O17)&""),0)=IFERROR(--(INDEX('Reguler Class Availability'!$F:$F,O17)&""),0),"Penuh",IF(IFERROR(--(INDEX('Reguler Class Availability'!$G:$G,O17)&""),0)=0,IF(INDEX('Reguler Class Availability'!$B:$B,O17)&""="","Kosong","Belum terisi"),IF(IFERROR(--(INDEX('Reguler Class Availability'!$G:$G,O17)&""),0)/IFERROR(--(INDEX('Reguler Class Availability'!$F:$F,O17)&""),0)>=0.6,"Tinggi","Sebagian")))))) -> Penuh | X17: =IF(P17="","",IF(AND(IFERROR(--(INDEX('Reguler Class Availability'!$F:$F,P17)&""),0)=0,IFERROR(--(INDEX('Reguler Class Availability'!$G:$G,P17)&""),0)=0),IF(OR(INDEX('Reguler Class Availability'!$B:$B,P17)&""<>"",INDEX('Reguler Class Availability'!$I:$I,P17)&""<>""),"Tutup","Tidak dibuka"),IF(IFERROR(--(INDEX('Reguler Class Availability'!$G:$G,P17)&""),0)>IFERROR(--(INDEX('Reguler Class Availability'!$F:$F,P17)&""),0),"Lebih",IF(IFERROR(--(INDEX('Reguler Class Availability'!$G:$G,P17)&""),0)=IFERROR(--(INDEX('Reguler Class Availability'!$F:$F,P17)&""),0),"Penuh",IF(IFERROR(--(INDEX('Reguler Class Availability'!$G:$G,P17)&""),0)=0,IF(INDEX('Reguler Class Availability'!$B:$B,P17)&""="","Kosong","Belum terisi"),IF(IFERROR(--(INDEX('Reguler Class Availability'!$G:$G,P17)&""),0)/IFERROR(--(INDEX('Reguler Class Availability'!$F:$F,P17)&""),0)>=0.6,"Tinggi","Sebagian")))))) -> Penuh | Z17: 09:45 | AA17: =IF(COUNTIFS('Reguler Class Availability'!$L:$L,$B$4&"|- Lane 1 - *|"&Z17)>0,1,0) -> 1 | AB17: =AA17+AB16 -> 4
