Workbook

Sheet Cara Pakai
B2: Slot Map Weekly Meeting · Center Manager × Senior Coach
B3: Data per 26 Sep 2026 · untuk meeting W40 · 28 Sep – 4 Okt 2026 · sumber: Exboard › Reguler Class Availability
B5: Alur meeting
B6: 1. Buka tab center | C6: Satu tab per center (KLM, KWC, PML, TMP, BTU, HIB). Mulai dari ringkasan di atas: utilisasi, jumlah kelas belum terisi, slot kosong.
B7: 2. Lihat Slot Map | C7: Grid per lane: baris = jam, kolom = hari. Tiap sel berisi age group, terisi/kapasitas, dan coach. Merah = kelas sudah ada tapi 0 murid. Oranye = kapasitas ada tapi belum ada kelas.
B8: 3. Putuskan di Daftar Diskusi | C8: Di bawah slot map ada daftar semua slot merah & oranye. Isi kolom kuning: keputusan, age group yang dijual, coach PIC, target murid, catatan.
B9: 4. Cek coach | C9: Kolom 'Coach available' menyarankan coach yang bertugas hari itu dan tidak sedang mengajar di jam tersebut, beserta age group yang biasa mereka ajar. Tabel Coach di bagian bawah tab menunjukkan beban tiap coach per hari.
B10: 5. Kirim ke Student Advisor | C10: Filter kolom Keputusan = 'Jual minggu ini' atau 'Buka kelas baru'. Itulah daftar kelas yang dijual SA minggu itu.
B12: Arti warna status
B13: Belum terisi | C13: Kelas sudah punya age group, kapasitas > 0, tapi 0 murid. Prioritas untuk dijual.
B14: Slot kosong | C14: Kapasitas > 0 tapi belum ada age group/kelas. Bisa dibuka jadi kelas baru.
B15: Sebagian | C15: Sudah ada murid tapi belum penuh.
B16: Penuh | C16: Terisi = kapasitas.
B17: Lebih kapasitas | C17: Terisi melebihi kapasitas (termasuk slot kapasitas 0 yang masih ada murid). Perlu dicek.
B18: Tutup | C18: Kapasitas 0 dan tidak ada murid, tapi slot masih punya age group/coach.
B19: Tidak dibuka | C19: Kapasitas 0, tanpa kelas. Ditampilkan '–'.
B21: Sel yang diisi
B22: Kuning | C22: Hanya sel kuning yang diisi saat meeting (minggu, peserta, keputusan, age group dijual, coach PIC, target, catatan). Sel lain berisi rumus.
B23: Teks biru | C23: Di tab Master Data: angka yang disalin dari Exboard (age group, kapasitas, terisi, coach).
B25: Contoh pengisian
B26: Hari · Jam · Lane | C26: Selasa · 09:45 · Lane 2
B27: Status | C27: Belum terisi
B28: Coach available | C28: Danti (Baby, Little)
B29: Keputusan | C29: Jual minggu ini
B30: Age group dijual | C30: Tiny
B31: Coach PIC | C31: Danti
B32: Target murid | C32: 3
B33: Catatan | C33: Tawarkan ke leads trial Tiny minggu lalu
B35: Catatan
B36: • | C36: Coach available = coach yang punya jadwal di center itu pada hari yang sama dan tidak mengajar dalam rentang ±45 menit dari slot tersebut. Age group di dalam kurung = age group yang dia ajar minggu ini di center itu. Ini saran; cek ulang ke senior coach.
B37: • | C37: Coach yang tidak punya jadwal sama sekali di hari itu tidak muncul sebagai available (bisa saja libur).
B38: • | C38: Untuk memperbarui data minggu berikutnya: ganti isi tab Master Data (kolom biru) dengan data terbaru. Slot map, ringkasan dan status ikut menghitung ulang. Daftar Diskusi dan saran coach dibuat saat file digenerate, jadi generate ulang file-nya tiap minggu.

Sheet Ringkasan
B2: Ringkasan Utilisasi per Center
B3: Data per 26 Sep 2026 · meeting W40 · 28 Sep – 4 Okt 2026
B5: Center | C5: Utilisasi | D5: Kursi terisi | E5: Kapasitas | F5: Belum terisi (kelas 0 murid) | G5: Slot kosong (belum ada kelas) | H5: Sebagian | I5: Penuh | J5: Lebih kapasitas | K5: Buka tab
B6: KLM | C6: =IFERROR(D6/E6,"") -> 0.56907216 | D6: =SUMIFS('Master Data'!$H$2:$H$2436,'Master Data'!$B$2:$B$2436,B6,'Master Data'!$G$2:$G$2436,">0") -> 828 | E6: =SUMIFS('Master Data'!$G$2:$G$2436,'Master Data'!$B$2:$B$2436,B6,'Master Data'!$G$2:$G$2436,">0") -> 1455 | F6: =COUNTIFS('Master Data'!$B$2:$B$2436,$B6,'Master Data'!$L$2:$L$2436,"Belum terisi") -> 48 | G6: =COUNTIFS('Master Data'!$B$2:$B$2436,$B6,'Master Data'!$L$2:$L$2436,"Slot kosong") -> 56 | H6: =COUNTIFS('Master Data'!$B$2:$B$2436,$B6,'Master Data'!$L$2:$L$2436,"Sebagian") -> 101 | I6: =COUNTIFS('Master Data'!$B$2:$B$2436,$B6,'Master Data'!$L$2:$L$2436,"Penuh") -> 131 | J6: =COUNTIFS('Master Data'!$B$2:$B$2436,$B6,'Master Data'!$L$2:$L$2436,"Lebih kapasitas") -> 18 | K6: → KLM
B7: KWC | C7: =IFERROR(D7/E7,"") -> 0.3956743 | D7: =SUMIFS('Master Data'!$H$2:$H$2436,'Master Data'!$B$2:$B$2436,B7,'Master Data'!$G$2:$G$2436,">0") -> 622 | E7: =SUMIFS('Master Data'!$G$2:$G$2436,'Master Data'!$B$2:$B$2436,B7,'Master Data'!$G$2:$G$2436,">0") -> 1572 | F7: =COUNTIFS('Master Data'!$B$2:$B$2436,$B7,'Master Data'!$L$2:$L$2436,"Belum terisi") -> 110 | G7: =COUNTIFS('Master Data'!$B$2:$B$2436,$B7,'Master Data'!$L$2:$L$2436,"Slot kosong") -> 35 | H7: =COUNTIFS('Master Data'!$B$2:$B$2436,$B7,'Master Data'!$L$2:$L$2436,"Sebagian") -> 125 | I7: =COUNTIFS('Master Data'!$B$2:$B$2436,$B7,'Master Data'!$L$2:$L$2436,"Penuh") -> 76 | J7: =COUNTIFS('Master Data'!$B$2:$B$2436,$B7,'Master Data'!$L$2:$L$2436,"Lebih kapasitas") -> 3 | K7: → KWC
B8: PML | C8: =IFERROR(D8/E8,"") -> 0.39257101 | D8: =SUMIFS('Master Data'!$H$2:$H$2436,'Master Data'!$B$2:$B$2436,B8,'Master Data'!$G$2:$G$2436,">0") -> 539 | E8: =SUMIFS('Master Data'!$G$2:$G$2436,'Master Data'!$B$2:$B$2436,B8,'Master Data'!$G$2:$G$2436,">0") -> 1373 | F8: =COUNTIFS('Master Data'!$B$2:$B$2436,$B8,'Master Data'!$L$2:$L$2436,"Belum terisi") -> 107 | G8: =COUNTIFS('Master Data'!$B$2:$B$2436,$B8,'Master Data'!$L$2:$L$2436,"Slot kosong") -> 33 | H8: =COUNTIFS('Master Data'!$B$2:$B$2436,$B8,'Master Data'!$L$2:$L$2436,"Sebagian") -> 99 | I8: =COUNTIFS('Master Data'!$B$2:$B$2436,$B8,'Master Data'!$L$2:$L$2436,"Penuh") -> 71 | J8: =COUNTIFS('Master Data'!$B$2:$B$2436,$B8,'Master Data'!$L$2:$L$2436,"Lebih kapasitas") -> 9 | K8: → PML
B9: TMP | C9: =IFERROR(D9/E9,"") -> 0.077380952 | D9: =SUMIFS('Master Data'!$H$2:$H$2436,'Master Data'!$B$2:$B$2436,B9,'Master Data'!$G$2:$G$2436,">0") -> 117 | E9: =SUMIFS('Master Data'!$G$2:$G$2436,'Master Data'!$B$2:$B$2436,B9,'Master Data'!$G$2:$G$2436,">0") -> 1512 | F9: =COUNTIFS('Master Data'!$B$2:$B$2436,$B9,'Master Data'!$L$2:$L$2436,"Belum terisi") -> 269 | G9: =COUNTIFS('Master Data'!$B$2:$B$2436,$B9,'Master Data'!$L$2:$L$2436,"Slot kosong") -> 0 | H9: =COUNTIFS('Master Data'!$B$2:$B$2436,$B9,'Master Data'!$L$2:$L$2436,"Sebagian") -> 66 | I9: =COUNTIFS('Master Data'!$B$2:$B$2436,$B9,'Master Data'!$L$2:$L$2436,"Penuh") -> 1 | J9: =COUNTIFS('Master Data'!$B$2:$B$2436,$B9,'Master Data'!$L$2:$L$2436,"Lebih kapasitas") -> 0 | K9: → TMP
B10: BTU | C10: =IFERROR(D10/E10,"") -> 0.096320346 | D10: =SUMIFS('Master Data'!$H$2:$H$2436,'Master Data'!$B$2:$B$2436,B10,'Master Data'!$G$2:$G$2436,">0") -> 178 | E10: =SUMIFS('Master Data'!$G$2:$G$2436,'Master Data'!$B$2:$B$2436,B10,'Master Data'!$G$2:$G$2436,">0") -> 1848 | F10: =COUNTIFS('Master Data'!$B$2:$B$2436,$B10,'Master Data'!$L$2:$L$2436,"Belum terisi") -> 263 | G10: =COUNTIFS('Master Data'!$B$2:$B$2436,$B10,'Master Data'!$L$2:$L$2436,"Slot kosong") -> 84 | H10: =COUNTIFS('Master Data'!$B$2:$B$2436,$B10,'Master Data'!$L$2:$L$2436,"Sebagian") -> 61 | I10: =COUNTIFS('Master Data'!$B$2:$B$2436,$B10,'Master Data'!$L$2:$L$2436,"Penuh") -> 12 | J10: =COUNTIFS('Master Data'!$B$2:$B$2436,$B10,'Master Data'!$L$2:$L$2436,"Lebih kapasitas") -> 0 | K10: → BTU
B11: HIB | C11: =IFERROR(D11/E11,"") -> 0.091991342 | D11: =SUMIFS('Master Data'!$H$2:$H$2436,'Master Data'!$B$2:$B$2436,B11,'Master Data'!$G$2:$G$2436,">0") -> 170 | E11: =SUMIFS('Master Data'!$G$2:$G$2436,'Master Data'!$B$2:$B$2436,B11,'Master Data'!$G$2:$G$2436,">0") -> 1848 | F11: =COUNTIFS('Master Data'!$B$2:$B$2436,$B11,'Master Data'!$L$2:$L$2436,"Belum terisi") -> 244 | G11: =COUNTIFS('Master Data'!$B$2:$B$2436,$B11,'Master Data'!$L$2:$L$2436,"Slot kosong") -> 84 | H11: =COUNTIFS('Master Data'!$B$2:$B$2436,$B11,'Master Data'!$L$2:$L$2436,"Sebagian") -> 82 | I11: =COUNTIFS('Master Data'!$B$2:$B$2436,$B11,'Master Data'!$L$2:$L$2436,"Penuh") -> 10 | J11: =COUNTIFS('Master Data'!$B$2:$B$2436,$B11,'Master Data'!$L$2:$L$2436,"Lebih kapasitas") -> 0 | K11: → HIB
B12: Total | C12: =IFERROR(D12/E12,"") -> 0.25541216 | D12: =SUM(D6:D11) -> 2454 | E12: =SUM(E6:E11) -> 9608 | F12: =SUM(F6:F11) -> 1041 | G12: =SUM(G6:G11) -> 292 | H12: =SUM(H6:H11) -> 534 | I12: =SUM(I6:I11) -> 301 | J12: =SUM(J6:J11) -> 30
B14: Utilisasi = kursi terisi ÷ kapasitas, hanya slot dengan kapasitas > 0.

Sheet KLM
A1: SLOT MAP · KLM · Kalimalang
A2: Data per 26 Sep 2026 · sumber: Exboard › Reguler Class Availability
A3: Center | B3: KLM | C3: Center Manager
A4: Minggu | B4: W40 · 28 Sep – 4 Okt 2026 | C4: Senior Coach
A6: Ringkasan | B6: Utilisasi | C6: Kursi terisi | D6: Belum terisi | E6: Slot kosong | F6: Sebagian | G6: Penuh | H6: Lebih kapasitas
B7: =IFERROR(SUMIFS('Master Data'!$H$2:$H$2436,'Master Data'!$B$2:$B$2436,$B$3,'Master Data'!$G$2:$G$2436,">0")/SUMIFS('Master Data'!$G$2:$G$2436,'Master Data'!$B$2:$B$2436,$B$3,'Master Data'!$G$2:$G$2436,">0"),"") -> 0.56907216 | C7: =SUMIFS('Master Data'!$H$2:$H$2436,'Master Data'!$B$2:$B$2436,$B$3,'Master Data'!$G$2:$G$2436,">0")&" / "&SUMIFS('Master Data'!$G$2:$G$2436,'Master Data'!$B$2:$B$2436,$B$3,'Master Data'!$G$2:$G$2436,">0") -> 828 / 1455 | D7: =COUNTIFS('Master Data'!$B$2:$B$2436,$B$3,'Master Data'!$L$2:$L$2436,"Belum terisi") -> 48 | E7: =COUNTIFS('Master Data'!$B$2:$B$2436,$B$3,'Master Data'!$L$2:$L$2436,"Slot kosong") -> 56 | F7: =COUNTIFS('Master Data'!$B$2:$B$2436,$B$3,'Master Data'!$L$2:$L$2436,"Sebagian") -> 101 | G7: =COUNTIFS('Master Data'!$B$2:$B$2436,$B$3,'Master Data'!$L$2:$L$2436,"Penuh") -> 131 | H7: =COUNTIFS('Master Data'!$B$2:$B$2436,$B$3,'Master Data'!$L$2:$L$2436,"Lebih kapasitas") -> 18
A9: Warna | B9: Belum terisi | C9: Slot kosong | D9: Sebagian | E9: Penuh | F9: Lebih kapasitas | G9: Tutup
B10: Isi sel: age group terisi/kapasitas, lalu coach. Merah & oranye = bahan diskusi (lihat Daftar Diskusi di bawah).
A11: Lompat ke | B11: → Slot Map | C11: → Daftar Diskusi | D11: → Coach
A13: LANE 1 | C13: ="Utilisasi lane: "&IFERROR(TEXT(SUMIFS('Master Data'!$H$2:$H$2436,'Master Data'!$B$2:$B$2436,$B$3,'Master Data'!$C$2:$C$2436,1,'Master Data'!$G$2:$G$2436,">0")/SUMIFS('Master Data'!$G$2:$G$2436,'Master Data'!$B$2:$B$2436,$B$3,'Master Data'!$C$2:$C$2436,1,'Master Data'!$G$2:$G$2436,">0"),"0%"),"–")&" · Belum terisi: "&COUNTIFS('Master Data'!$B$2:$B$2436,$B$3,'Master Data'!$C$2:$C$2436,1,'Master Data'!$L$2:$L$2436,"Belum terisi")&" · Slot kosong: "&COUNTIFS('Master Data'!$B$2:$B$2436,$B$3,'Master Data'!$C$2:$C$2436,1,'Master Data'!$L$2:$L$2436,"Slot kosong") -> Utilisasi lane: 41% · Belum terisi: 1 · Slot kosong: 27
A14: Jam | B14: Senin | C14: Selasa | D14: Rabu | E14: Kamis | F14: Jumat | G14: Sabtu | H14: Minggu
A15: 08:15 | B15: =IFERROR(INDEX('Master Data'!$M$2:$M$2436,MATCH($B$3&"|1|"&B$14&"|"&$A15,'Master Data'!$A$2:$A$2436,0)),"") -> – | C15: =IFERROR(INDEX('Master Data'!$M$2:$M$2436,MATCH($B$3&"|1|"&C$14&"|"&$A15,'Master Data'!$A$2:$A$2436,0)),"") -> – | D15: =IFERROR(INDEX('Master Data'!$M$2:$M$2436,MATCH($B$3&"|1|"&D$14&"|"&$A15,'Master Data'!$A$2:$A$2436,0)),"") -> – | E15: =IFERROR(INDEX('Master Data'!$M$2:$M$2436,MATCH($B$3&"|1|"&E$14&"|"&$A15,'Master Data'!$A$2:$A$2436,0)),"") -> – | F15: =IFERROR(INDEX('Master Data'!$M$2:$M$2436,MATCH($B$3&"|1|"&F$14&"|"&$A15,'Master Data'!$A$2:$A$2436,0)),"") -> – | G15: =IFERROR(INDEX('Master Data'!$M$2:$M$2436,MATCH($B$3&"|1|"&G$14&"|"&$A15,'Master Data'!$A$2:$A$2436,0)),"") -> – | H15: =IFERROR(INDEX('Master Data'!$M$2:$M$2436,MATCH($B$3&"|1|"&H$14&"|"&$A15,'Master Data'!$A$2:$A$2436,0)),"") -> – | T15: =IFERROR(INDEX('Master Data'!$L$2:$L$2436,MATCH($B$3&"|1|"&B$14&"|"&$A15,'Master Data'!$A$2:$A$2436,0)),"") -> Tidak dibuka | U15: =IFERROR(INDEX('Master Data'!$L$2:$L$2436,MATCH($B$3&"|1|"&C$14&"|"&$A15,'Master Data'!$A$2:$A$2436,0)),"") -> Tidak dibuka | V15: =IFERROR(INDEX('Master Data'!$L$2:$L$2436,MATCH($B$3&"|1|"&D$14&"|"&$A15,'Master Data'!$A$2:$A$2436,0)),"") -> Tidak dibuka | W15: =IFERROR(INDEX('Master Data'!$L$2:$L$2436,MATCH($B$3&"|1|"&E$14&"|"&$A15,'Master Data'!$A$2:$A$2436,0)),"") -> Tidak dibuka | X15: =IFERROR(INDEX('Master Data'!$L$2:$L$2436,MATCH($B$3&"|1|"&F$14&"|"&$A15,'Master Data'!$A$2:$A$2436,0)),"") -> Tidak dibuka | Y15: =IFERROR(INDEX('Master Data'!$L$2:$L$2436,MATCH($B$3&"|1|"&G$14&"|"&$A15,'Master Data'!$A$2:$A$2436,0)),"") -> Tidak dibuka | Z15: =IFERROR(INDEX('Master Data'!$L$2:$L$2436,MATCH($B$3&"|1|"&H$14&"|"&$A15,'Master Data'!$A$2:$A$2436,0)),"") -> Tidak dibuka
A16: 09:00 | B16: =IFERROR(INDEX('Master Data'!$M$2:$M$2436,MATCH($B$3&"|1|"&B$14&"|"&$A16,'Master Data'!$A$2:$A$2436,0)),"") -> (tanpa age group) 0/5 coach: – | C16: =IFERROR(INDEX('Master Data'!$M$2:$M$2436,MATCH($B$3&"|1|"&C$14&"|"&$A16,'Master Data'!$A$2:$A$2436,0)),"") -> (tanpa age group) 0/5 coach: – | D16: =IFERROR(INDEX('Master Data'!$M$2:$M$2436,MATCH($B$3&"|1|"&D$14&"|"&$A16,'Master Data'!$A$2:$A$2436,0)),"") -> Baby 5/5 coach: Nuky | E16: =IFERROR(INDEX('Master Data'!$M$2:$M$2436,MATCH($B$3&"|1|"&E$14&"|"&$A16,'Master Data'!$A$2:$A$2436,0)),"") -> (tanpa age group) 0/5 coach: – | F16: =IFERROR(INDEX('Master Data'!$M$2:$M$2436,MATCH($B$3&"|1|"&F$14&"|"&$A16,'Master Data'!$A$2:$A$2436,0)),"") -> Baby 5/5 coach: Surya | G16: =IFERROR(INDEX('Master Data'!$M$2:$M$2436,MATCH($B$3&"|1|"&G$14&"|"&$A16,'Master Data'!$A$2:$A$2436,0)),"") -> Baby 5/5 coach: Eka | H16: =IFERROR(INDEX('Master Data'!$M$2:$M$2436,MATCH($B$3&"|1|"&H$14&"|"&$A16,'Master Data'!$A$2:$A$2436,0)),"") -> Baby 5/5 coach: Rischa | T16: =IFERROR(INDEX('Master Data'!$L$2:$L$2436,MATCH($B$3&"|1|"&B$14&"|"&$A16,'Master Data'!$A$2:$A$2436,0)),"") -> Slot kosong | U16: =IFERROR(INDEX('Master Data'!$L$2:$L$2436,MATCH($B$3&"|1|"&C$14&"|"&$A16,'Master Data'!$A$2:$A$2436,0)),"") -> Slot kosong | V16: =IFERROR(INDEX('Master Data'!$L$2:$L$2436,MATCH($B$3&"|1|"&D$14&"|"&$A16,'Master Data'!$A$2:$A$2436,0)),"") -> Penuh | W16: =IFERROR(INDEX('Master Data'!$L$2:$L$2436,MATCH($B$3&"|1|"&E$14&"|"&$A16,'Master Data'!$A$2:$A$2436,0)),"") -> Slot kosong | X16: =IFERROR(INDEX('Master Data'!$L$2:$L$2436,MATCH($B$3&"|1|"&F$14&"|"&$A16,'Master Data'!$A$2:$A$2436,0)),"") -> Penuh | Y16: =IFERROR(INDEX('Master Data'!$L$2:$L$2436,MATCH($B$3&"|1|"&G$14&"|"&$A16,'Master Data'!$A$2:$A$2436,0)),"") -> Penuh | Z16: =IFERROR(INDEX('Master Data'!$L$2:$L$2436,MATCH($B$3&"|1|"&H$14&"|"&$A16,'Master Data'!$A$2:$A$2436,0)),"") -> Penuh
A17: 09:45 | B17: =IFERROR(INDEX('Master Data'!$M$2:$M$2436,MATCH($B$3&"|1|"&B$14&"|"&$A17,'Master Data'!$A$2:$A$2436,0)),"") -> (tanpa age group) 0/5 coach: – | C17: =IFERROR(INDEX('Master Data'!$M$2:$M$2436,MATCH($B$3&"|1|"&C$14&"|"&$A17,'Master Data'!$A$2:$A$2436,0)),"") -> (tanpa age group) 0/5 coach: – | D17: =IFERROR(INDEX('Master Data'!$M$2:$M$2436,MATCH($B$3&"|1|"&D$14&"|"&$A17,'Master Data'!$A$2:$A$2436,0)),"") -> (tanpa age group) 0/5 coach: – | E17: =IFERROR(INDEX('Master Data'!$M$2:$M$2436,MATCH($B$3&"|1|"&E$14&"|"&$A17,'Master Data'!$A$2:$A$2436,0)),"") -> (tanpa age group) 0/5 coach: – | F17: =IFERROR(INDEX('Master Data'!$M$2:$M$2436,MATCH($B$3&"|1|"&F$14&"|"&$A17,'Master Data'!$A$2:$A$2436,0)),"") -> (tanpa age group) 0/5 coach: – | G17: =IFERROR(INDEX('Master Data'!$M$2:$M$2436,MATCH($B$3&"|1|"&G$14&"|"&$A17,'Master Data'!$A$2:$A$2436,0)),"") -> Baby 5/5 coach: Rischa | H17: =IFERROR(INDEX('Master Data'!$M$2:$M$2436,MATCH($B$3&"|1|"&H$14&"|"&$A17,'Master Data'!$A$2:$A$2436,0)),"") -> Baby 5/5 coach: Zidane | T17: =IFERROR(INDEX('Master Data'!$L$2:$L$2436,MATCH($B$3&"|1|"&B$14&"|"&$A17,'Master Data'!$A$2:$A$2436,0)),"") -> Slot kosong | U17: =IFERROR(INDEX('Master Data'!$L$2:$L$2436,MATCH($B$3&"|1|"&C$14&"|"&$A17,'Master Data'!$A$2:$A$2436,0)),"") -> Slot kosong | V17: =IFERROR(INDEX('Master Data'!$L$2:$L$2436,MATCH($B$3&"|1|"&D$14&"|"&$A17,'Master Data'!$A$2:$A$2436,0)),"") -> Slot kosong | W17: =IFERROR(INDEX('Master Data'!$L$2:$L$2436,MATCH($B$3&"|1|"&E$14&"|"&$A17,'Master Data'!$A$2:$A$2436,0)),"") -> Slot kosong | X17: =IFERROR(INDEX('Master Data'!$L$2:$L$2436,MATCH($B$3&"|1|"&F$14&"|"&$A17,'Master Data'!$A$2:$A$2436,0)),"") -> Slot kosong | Y17: =IFERROR(INDEX('Master Data'!$L$2:$L$2436,MATCH($B$3&"|1|"&G$14&"|"&$A17,'Master Data'!$A$2:$A$2436,0)),"") -> Penuh | Z17: =IFERROR(INDEX('Master Data'!$L$2:$L$2436,MATCH($B$3&"|1|"&H$14&"|"&$A17,'Master Data'!$A$2:$A$2436,0)),"") -> Penuh
A18: 10:30 | B18: =IFERROR(INDEX('Master Data'!$M$2:$M$2436,MATCH($B$3&"|1|"&B$14&"|"&$A18,'Master Data'!$A$2:$A$2436,0)),"") -> Baby 1/5 coach: Danti | C18: =IFERROR(INDEX('Master Data'!$M$2:$M$2436,MATCH($B$3&"|1|"&C$14&"|"&$A18,'Master Data'!$A$2:$A$2436,0)),"") -> Baby 1/5 coach: Zidane | D18: =IFERROR(INDEX('Master Data'!$M$2:$M$2436,MATCH($B$3&"|1|"&D$14&"|"&$A18,'Master Data'!$A$2:$A$2436,0)),"") -> (tanpa age group) 0/5 coach: – | E18: =IFERROR(INDEX('Master Data'!$M$2:$M$2436,MATCH($B$3&"|1|"&E$14&"|"&$A18,'Master Data'!$A$2:$A$2436,0)),"") -> (tanpa age group) 0/5 coach: – | F18: =IFERROR(INDEX('Master Data'!$M$2:$M$2436,MATCH($B$3&"|1|"&F$14&"|"&$A18,'Master Data'!$A$2:$A$2436,0)),"") -> (tanpa age group) 0/5 coach: – | G18: =IFERROR(INDEX('Master Data'!$M$2:$M$2436,MATCH($B$3&"|1|"&G$14&"|"&$A18,'Master Data'!$A$2:$A$2436,0)),"") -> Baby 5/5 coach: Rischa | H18: =IFERROR(INDEX('Master Data'!$M$2:$M$2436,MATCH($B$3&"|1|"&H$14&"|"&$A18,'Master Data'!$A$2:$A$2436,0)),"") -> Baby 4/5 coach: Nuky | T18: =IFERROR(INDEX('Master Data'!$L$2:$L$2436,MATCH($B$3&"|1|"&B$14&"|"&$A18,'Master Data'!$A$2:$A$2436,0)),"") -> Sebagian | U18: =IFERROR(INDEX('Master Data'!$L$2:$L$2436,MATCH($B$3&"|1|"&C$14&"|"&$A18,'Master Data'!$A$2:$A$2436,0)),"") -> Sebagian | V18: =IFERROR(INDEX('Master Data'!$L$2:$L$2436,MATCH($B$3&"|1|"&D$14&"|"&$A18,'Master Data'!$A$2:$A$2436,0)),"") -> Slot kosong | W18: =IFERROR(INDEX('Master Data'!$L$2:$L$2436,MATCH($B$3&"|1|"&E$14&"|"&$A18,'Master Data'!$A$2:$A$2436,0)),"") -> Slot kosong | X18: =IFERROR(INDEX('Master Data'!$L$2:$L$2436,MATCH($B$3&"|1|"&F$14&"|"&$A18,'Master Data'!$A$2:$A$2436,0)),"") -> Slot kosong | Y18: =IFERROR(INDEX('Master Data'!$L$2:$L$2436,MATCH($B$3&"|1|"&G$14&"|"&$A18,'Master Data'!$A$2:$A$2436,0)),"") -> Penuh | Z18: =IFERROR(INDEX('Master Data'!$L$2:$L$2436,MATCH($B$3&"|1|"&H$14&"|"&$A18,'Master Data'!$A$2:$A$2436,0)),"") -> Sebagian
A19: 11:15 | B19: =IFERROR(INDEX('Master Data'!$M$2:$M$2436,MATCH($B$3&"|1|"&B$14&"|"&$A19,'Master Data'!$A$2:$A$2436,0)),"") -> (tanpa age group) 0/5 coach: – | C19: =IFERROR(INDEX('Master Data'!$M$2:$M$2436,MATCH($B$3&"|1|"&C$14&"|"&$A19,'Master Data'!$A$2:$A$2436,0)),"") -> Baby 2/5 coach: Zidane | D19: =IFERROR(INDEX('Master Data'!$M$2:$M$2436,MATCH($B$3&"|1|"&D$14&"|"&$A19,'Master Data'!$A$2:$A$2436,0)),"") -> Baby 2/5 coach: Nuky | E19: =IFERROR(INDEX('Master Data'!$M$2:$M$2436,MATCH($B$3&"|1|"&E$14&"|"&$A19,'Master Data'!$A$2:$A$2436,0)),"") -> (tanpa age group) 0/5 coach: – | F19: =IFERROR(INDEX('Master Data'!$M$2:$M$2436,MATCH($B$3&"|1|"&F$14&"|"&$A19,'Master Data'!$A$2:$A$2436,0)),"") -> (tanpa age group) 0/5 coach: – | G19: =IFERROR(INDEX('Master Data'!$M$2:$M$2436,MATCH($B$3&"|1|"&G$14&"|"&$A19,'Master Data'!$A$2:$A$2436,0)),"") -> Little 4/4 coach: Tessa | H19: =IFERROR(INDEX('Master Data'!$M$2:$M$2436,MATCH($B$3&"|1|"&H$14&"|"&$A19,'Master Data'!$A$2:$A$2436,0)),"") -> Little 4/4 coach: Gita | T19: =IFERROR(INDEX('Master Data'!$L$2:$L$2436,MATCH($B$3&"|1|"&B$14&"|"&$A19,'Master Data'!$A$2:$A$2436,0)),"") -> Slot kosong | U19: =IFERROR(INDEX('Master Data'!$L$2:$L$2436,MATCH($B$3&"|1|"&C$14&"|"&$A19,'Master Data'!$A$2:$A$2436,0)),"") -> Sebagian | V19: =IFERROR(INDEX('Master Data'!$L$2:$L$2436,MATCH($B$3&"|1|"&D$14&"|"&$A19,'Master Data'!$A$2:$A$2436,0)),"") -> Sebagian | W19: =IFERROR(INDEX('Master Data'!$L$2:$L$2436,MATCH($B$3&"|1|"&E$14&"|"&$A19,'Master Data'!$A$2:$A$2436,0)),"") -> Slot kosong | X19: =IFERROR(INDEX('Master Data'!$L$2:$L$2436,MATCH($B$3&"|1|"&F$14&"|"&$A19,'Master Data'!$A$2:$A$2436,0)),"") -> Slot kosong | Y19: =IFERROR(INDEX('Master Data'!$L$2:$L$2436,MATCH($B$3&"|1|"&G$14&"|"&$A19,'Master Data'!$A$2:$A$2436,0)),"") -> Penuh | Z19: =IFERROR(INDEX('Master Data'!$L$2:$L$2436,MATCH($B$3&"|1|"&H$14&"|"&$A19,'Master Data'!$A$2:$A$2436,0)),"") -> Penuh
A20: 12:00 | B20: =IFERROR(INDEX('Master Data'!$M$2:$M$2436,MATCH($B$3&"|1|"&B$14&"|"&$A20,'Master Data'!$A$2:$A$2436,0)),"") -> Baby 3/5 coach: Danti | C20: =IFERROR(INDEX('Master Data'!$M$2:$M$2436,MATCH($B$3&"|1|"&C$14&"|"&$A20,'Master Data'!$A$2:$A$2436,0)),"") -> – | D20: =IFERROR(INDEX('Master Data'!$M$2:$M$2436,MATCH($B$3&"|1|"&D$14&"|"&$A20,'Master Data'!$A$2:$A$2436,0)),"") -> – | E20: =IFERROR(INDEX('Master Data'!$M$2:$M$2436,MATCH($B$3&"|1|"&E$14&"|"&$A20,'Master Data'!$A$2:$A$2436,0)),"") -> – | F20: =IFERROR(INDEX('Master Data'!$M$2:$M$2436,MATCH($B$3&"|1|"&F$14&"|"&$A20,'Master Data'!$A$2:$A$2436,0)),"") -> – | G20: =IFERROR(INDEX('Master Data'!$M$2:$M$2436,MATCH($B$3&"|1|"&G$14&"|"&$A20,'Master Data'!$A$2:$A$2436,0)),"") -> Little 2/4 coach: Daffa | H20: =IFERROR(INDEX('Master Data'!$M$2:$M$2436,MATCH($B$3&"|1|"&H$14&"|"&$A20,'Master Data'!$A$2:$A$2436,0)),"") -> (tanpa age group) 0/5 coach: – | T20: =IFERROR(INDEX('Master Data'!$L$2:$L$2436,MATCH($B$3&"|1|"&B$14&"|"&$A20,'Master Data'!$A$2:$A$2436,0)),"") -> Sebagian | U20: =IFERROR(INDEX('Master Data'!$L$2:$L$2436,MATCH($B$3&"|1|"&C$14&"|"&$A20,'Master Data'!$A$2:$A$2436,0)),"") -> Tidak dibuka | V20: =IFERROR(INDEX('Master Data'!$L$2:$L$2436,MATCH($B$3&"|1|"&D$14&"|"&$A20,'Master Data'!$A$2:$A$2436,0)),"") -> Tidak dibuka | W20: =IFERROR(INDEX('Master Data'!$L$2:$L$2436,MATCH($B$3&"|1|"&E$14&"|"&$A20,'Master Data'!$A$2:$A$2436,0)),"") -> Tidak dibuka | X20: =IFERROR(INDEX('Master Data'!$L$2:$L$2436,MATCH($B$3&"|1|"&F$14&"|"&$A20,'Master Data'!$A$2:$A$2436,0)),"") -> Tidak dibuka | Y20: =IFERROR(INDEX('Master Data'!$L$2:$L$2436,MATCH($B$3&"|1|"&G$14&"|"&$A20,'Master Data'!$A$2:$A$2436,0)),"") -> Sebagian | Z20: =IFERROR(INDEX('Master Data'!$L$2:$L$2436,MATCH($B$3&"|1|"&H$14&"|"&$A20,'Master Data'!$A$2:$A$2436,0)),"") -> Slot kosong
A21: 13:30 | B21: =IFERROR(INDEX('Master Data'!$M$2:$M$2436,MATCH($B$3&"|1|"&B$14&"|"&$A21,'Master Data'!$A$2:$A$2436,0)),"") -> Little 1/4 coach: Gita | C21: =IFERROR(INDEX('Master Data'!$M$2:$M$2436,MATCH($B$3&"|1|"&C$14&"|"&$A21,'Master Data'!$A$2:$A$2436,0)),"") -> (tanpa age group) 0/5 coach: – | D21: =IFERROR(INDEX('Master Data'!$M$2:$M$2436,MATCH($B$3&"|1|"&D$14&"|"&$A21,'Master Data'!$A$2:$A$2436,0)),"") -> Baby 0/5 coach: – | E21: =IFERROR(INDEX('Master Data'!$M$2:$M$2436,MATCH($B$3&"|1|"&E$14&"|"&$A21,'Master Data'!$A$2:$A$2436,0)),"") -> (tanpa age group) 0/5 coach: – | F21: =IFERROR(INDEX('Master Data'!$M$2:$M$2436,MATCH($B$3&"|1|"&F$14&"|"&$A21,'Master Data'!$A$2:$A$2436,0)),"") -> (tanpa age group) 0/5 coach: – | G21: =IFERROR(INDEX('Master Data'!$M$2:$M$2436,MATCH($B$3&"|1|"&G$14&"|"&$A21,'Master Data'!$A$2:$A$2436,0)),"") -> Baby 5/5 coach: Danti | H21: =IFERROR(INDEX('Master Data'!$M$2:$M$2436,MATCH($B$3&"|1|"&H$14&"|"&$A21,'Master Data'!$A$2:$A$2436,0)),"") -> Baby 3/5 coach: Eka | T21: =IFERROR(INDEX('Master Data'!$L$2:$L$2436,MATCH($B$3&"|1|"&B$14&"|"&$A21,'Master Data'!$A$2:$A$2436,0)),"") -> Sebagian | U21: =IFERROR(INDEX('Master Data'!$L$2:$L$2436,MATCH($B$3&"|1|"&C$14&"|"&$A21,'Master Data'!$A$2:$A$2436,0)),"") -> Slot kosong | V21: =IFERROR(INDEX('Master Data'!$L$2:$L$2436,MATCH($B$3&"|1|"&D$14&"|"&$A21,'Master Data'!$A$2:$A$2436,0)),"") -> Belum terisi | W21: =IFERROR(INDEX('Master Data'!$L$2:$L$2436,MATCH($B$3&"|1|"&E$14&"|"&$A21,'Master Data'!$A$2:$A$2436,0)),"") -> Slot kosong | X21: =IFERROR(INDEX('Master Data'!$L$2:$L$2436,MATCH($B$3&"|1|"&F$14&"|"&$A21,'Master Data'!$A$2:$A$2436,0)),"") -> Slot kosong | Y21: =IFERROR(INDEX('Master Data'!$L$2:$L$2436,MATCH($B$3&"|1|"&G$14&"|"&$A21,'Master Data'!$A$2:$A$2436,0)),"") -> Penuh | Z21: =IFERROR(INDEX('Master Data'!$L$2:$L$2436,MATCH($B$3&"|1|"&H$14&"|"&$A21,'Master Data'!$A$2:$A$2436,0)),"") -> Sebagian
A22: 14:15 | B22: =IFERROR(INDEX('Master Data'!$M$2:$M$2436,MATCH($B$3&"|1|"&B$14&"|"&$A22,'Master Data'!$A$2:$A$2436,0)),"") -> (tanpa age group) 0/5 coach: – | C22: =IFERROR(INDEX('Master Data'!$M$2:$M$2436,MATCH($B$3&"|1|"&C$14&"|"&$A22,'Master Data'!$A$2:$A$2436,0)),"") -> (tanpa age group) 0/5 coach: – | D22: =IFERROR(INDEX('Master Data'!$M$2:$M$2436,MATCH($B$3&"|1|"&D$14&"|"&$A22,'Master Data'!$A$2:$A$2436,0)),"") -> (tanpa age group) 0/5 coach: – | E22: =IFERROR(INDEX('Master Data'!$M$2:$M$2436,MATCH($B$3&"|1|"&E$14&"|"&$A22,'Master Data'!$A$2:$A$2436,0)),"") -> Kids 1/5 coach: Tessa | F22: =IFERROR(INDEX('Master Data'!$M$2:$M$2436,MATCH($B$3&"|1|"&F$14&"|"&$A22,'Master Data'!$A$2:$A$2436,0)),"") -> Kids 3/4 coach: Tessa | G22: =IFERROR(INDEX('Master Data'!$M$2:$M$2436,MATCH($B$3&"|1|"&G$14&"|"&$A22,'Master Data'!$A$2:$A$2436,0)),"") -> Kids 4/4 coach: Daffa | H22: =IFERROR(INDEX('Master Data'!$M$2:$M$2436,MATCH($B$3&"|1|"&H$14&"|"&$A22,'Master Data'!$A$2:$A$2436,0)),"") -> Kids 4/4 coach: Danti | T22: =IFERROR(INDEX('Master Data'!$L$2:$L$2436,MATCH($B$3&"|1|"&B$14&"|"&$A22,'Master Data'!$A$2:$A$2436,0)),"") -> Slot kosong | U22: =IFERROR(INDEX('Master Data'!$L$2:$L$2436,MATCH($B$3&"|1|"&C$14&"|"&$A22,'Master Data'!$A$2:$A$2436,0)),"") -> Slot kosong | V22: =IFERROR(INDEX('Master Data'!$L$2:$L$2436,MATCH($B$3&"|1|"&D$14&"|"&$A22,'Master Data'!$A$2:$A$2436,0)),"") -> Slot kosong | W22: =IFERROR(INDEX('Master Data'!$L$2:$L$2436,MATCH($B$3&"|1|"&E$14&"|"&$A22,'Master Data'!$A$2:$A$2436,0)),"") -> Sebagian | X22: =IFERROR(INDEX('Master Data'!$L$2:$L$2436,MATCH($B$3&"|1|"&F$14&"|"&$A22,'Master Data'!$A$2:$A$2436,0)),"") -> Sebagian | Y22: =IFERROR(INDEX('Master Data'!$L$2:$L$2436,MATCH($B$3&"|1|"&G$14&"|"&$A22,'Master Data'!$A$2:$A$2436,0)),"") -> Penuh | Z22: =IFERROR(INDEX('Master Data'!$L$2:$L$2436,MATCH($B$3&"|1|"&H$14&"|"&$A22,'Master Data'!$A$2:$A$2436,0)),"") -> Penuh
A23: 15:00 | B23: =IFERROR(INDEX('Master Data'!$M$2:$M$2436,MATCH($B$3&"|1|"&B$14&"|"&$A23,'Master Data'!$A$2:$A$2436,0)),"") -> Little 2/0 coach: Gita | C23: =IFERROR(INDEX('Master Data'!$M$2:$M$2436,MATCH($B$3&"|1|"&C$14&"|"&$A23,'Master Data'!$A$2:$A$2436,0)),"") -> Kids 4/0 coach: Tessa | D23: =IFERROR(INDEX('Master Data'!$M$2:$M$2436,MATCH($B$3&"|1|"&D$14&"|"&$A23,'Master Data'!$A$2:$A$2436,0)),"") -> Baby 1/0 coach: Zidane | E23: =IFERROR(INDEX('Master Data'!$M$2:$M$2436,MATCH($B$3&"|1|"&E$14&"|"&$A23,'Master Data'!$A$2:$A$2436,0)),"") -> Baby 1/0 coach: Tessa | F23: =IFERROR(INDEX('Master Data'!$M$2:$M$2436,MATCH($B$3&"|1|"&F$14&"|"&$A23,'Master Data'!$A$2:$A$2436,0)),"") -> Little 3/4 coach: Dian | G23: =IFERROR(INDEX('Master Data'!$M$2:$M$2436,MATCH($B$3&"|1|"&G$14&"|"&$A23,'Master Data'!$A$2:$A$2436,0)),"") -> Baby 5/5 coach: Eka | H23: =IFERROR(INDEX('Master Data'!$M$2:$M$2436,MATCH($B$3&"|1|"&H$14&"|"&$A23,'Master Data'!$A$2:$A$2436,0)),"") -> Baby 4/5 coach: Zidane | T23: =IFERROR(INDEX('Master Data'!$L$2:$L$2436,MATCH($B$3&"|1|"&B$14&"|"&$A23,'Master Data'!$A$2:$A$2436,0)),"") -> Lebih kapasitas | U23: =IFERROR(INDEX('Master Data'!$L$2:$L$2436,MATCH($B$3&"|1|"&C$14&"|"&$A23,'Master Data'!$A$2:$A$2436,0)),"") -> Lebih kapasitas | V23: =IFERROR(INDEX('Master Data'!$L$2:$L$2436,MATCH($B$3&"|1|"&D$14&"|"&$A23,'Master Data'!$A$2:$A$2436,0)),"") -> Lebih kapasitas | W23: =IFERROR(INDEX('Master Data'!$L$2:$L$2436,MATCH($B$3&"|1|"&E$14&"|"&$A23,'Master Data'!$A$2:$A$2436,0)),"") -> Lebih kapasitas | X23: =IFERROR(INDEX('Master Data'!$L$2:$L$2436,MATCH($B$3&"|1|"&F$14&"|"&$A23,'Master Data'!$A$2:$A$2436,0)),"") -> Sebagian | Y23: =IFERROR(INDEX('Master Data'!$L$2:$L$2436,MATCH($B$3&"|1|"&G$14&"|"&$A23,'Master Data'!$A$2:$A$2436,0)),"") -> Penuh | Z23: =IFERROR(INDEX('Master Data'!$L$2:$L$2436,MATCH($B$3&"|1|"&H$14&"|"&$A23,'Master Data'!$A$2:$A$2436,0)),"") -> Sebagian
A24: 15:45 | B24: =IFERROR(INDEX('Master Data'!$M$2:$M$2436,MATCH($B$3&"|1|"&B$14&"|"&$A24,'Master Data'!$A$2:$A$2436,0)),"") -> – | C24: =IFERROR(INDEX('Master Data'!$M$2:$M$2436,MATCH($B$3&"|1|"&C$14&"|"&$A24,'Master Data'!$A$2:$A$2436,0)),"") -> – | D24: =IFERROR(INDEX('Master Data'!$M$2:$M$2436,MATCH($B$3&"|1|"&D$14&"|"&$A24,'Master Data'!$A$2:$A$2436,0)),"") -> Little 3/0 coach: Gita | E24: =IFERROR(INDEX('Master Data'!$M$2:$M$2436,MATCH($B$3&"|1|"&E$14&"|"&$A24,'Master Data'!$A$2:$A$2436,0)),"") -> Kids 1/0 coach: Daffa | F24: =IFERROR(INDEX('Master Data'!$M$2:$M$2436,MATCH($B$3&"|1|"&F$14&"|"&$A24,'Master Data'!$A$2:$A$2436,0)),"") -> Kids 4/4 coach: Surya | G24: =IFERROR(INDEX('Master Data'!$M$2:$M$2436,MATCH($B$3&"|1|"&G$14&"|"&$A24,'Master Data'!$A$2:$A$2436,0)),"") -> Little 4/4 coach: Daffa | H24: =IFERROR(INDEX('Master Data'!$M$2:$M$2436,MATCH($B$3&"|1|"&H$14&"|"&$A24,'Master Data'!$A$2:$A$2436,0)),"") -> Kids 2/4 coach: Zidane | T24: =IFERROR(INDEX('Master Data'!$L$2:$L$2436,MATCH($B$3&"|1|"&B$14&"|"&$A24,'Master Data'!$A$2:$A$2436,0)),"") -> Tidak dibuka | U24: =IFERROR(INDEX('Master Data'!$L$2:$L$2436,MATCH($B$3&"|1|"&C$14&"|"&$A24,'Master Data'!$A$2:$A$2436,0)),"") -> Tidak dibuka | V24: =IFERROR(INDEX('Master Data'!$L$2:$L$2436,MATCH($B$3&"|1|"&D$14&"|"&$A24,'Master Data'!$A$2:$A$2436,0)),"") -> Lebih kapasitas | W24: =IFERROR(INDEX('Master Data'!$L$2:$L$2436,MATCH($B$3&"|1|"&E$14&"|"&$A24,'Master Data'!$A$2:$A$2436,0)),"") -> Lebih kapasitas | X24: =IFERROR(INDEX('Master Data'!$L$2:$L$2436,MATCH($B$3&"|1|"&F$14&"|"&$A24,'Master Data'!$A$2:$A$2436,0)),"") -> Penuh | Y24: =IFERROR(INDEX('Master Data'!$L$2:$L$2436,MATCH($B$3&"|1|"&G$14&"|"&$A24,'Master Data'!$A$2:$A$2436,0)),"") -> Penuh | Z24: =IFERROR(INDEX('Master Data'!$L$2:$L$2436,MATCH($B$3&"|1|"&H$14&"|"&$A24,'Master Data'!$A$2:$A$2436,0)),"") -> Sebagian
A25: 16:30 | B25: =IFERROR(INDEX('Master Data'!$M$2:$M$2436,MATCH($B$3&"|1|"&B$14&"|"&$A25,'Master Data'!$A$2:$A$2436,0)),"") -> Kids 3/5 coach: Gita | C25: =IFERROR(INDEX('Master Data'!$M$2:$M$2436,MATCH($B$3&"|1|"&C$14&"|"&$A25,'Master Data'!$A$2:$A$2436,0)),"") -> (tanpa age group) 0/5 coach: – | D25: =IFERROR(INDEX('Master Data'!$M$2:$M$2436,MATCH($B$3&"|1|"&D$14&"|"&$A25,'Master Data'!$A$2:$A$2436,0)),"") -> (tanpa age group) 0/5 coach: – | E25: =IFERROR(INDEX('Master Data'!$M$2:$M$2436,MATCH($B$3&"|1|"&E$14&"|"&$A25,'Master Data'!$A$2:$A$2436,0)),"") -> Kids 4/4 coach: Tessa | F25: =IFERROR(INDEX('Master Data'!$M$2:$M$2436,MATCH($B$3&"|1|"&F$14&"|"&$A25,'Master Data'!$A$2:$A$2436,0)),"") -> Little 3/4 coach: Tessa | G25: =IFERROR(INDEX('Master Data'!$M$2:$M$2436,MATCH($B$3&"|1|"&G$14&"|"&$A25,'Master Data'!$A$2:$A$2436,0)),"") -> Baby 4/5 coach: Danti | H25: =IFERROR(INDEX('Master Data'!$M$2:$M$2436,MATCH($B$3&"|1|"&H$14&"|"&$A25,'Master Data'!$A$2:$A$2436,0)),"") -> Little 1/4 coach: Dian | T25: =IFERROR(INDEX('Master Data'!$L$2:$L$2436,MATCH($B$3&"|1|"&B$14&"|"&$A25,'Master Data'!$A$2:$A$2436,0)),"") -> Sebagian | U25: =IFERROR(INDEX('Master Data'!$L$2:$L$2436,MATCH($B$3&"|1|"&C$14&"|"&$A25,'Master Data'!$A$2:$A$2436,0)),"") -> Slot kosong | V25: =IFERROR(INDEX('Master Data'!$L$2:$L$2436,MATCH($B$3&"|1|"&D$14&"|"&$A25,'Master Data'!$A$2:$A$2436,0)),"") -> Slot kosong | W25: =IFERROR(INDEX('Master Data'!$L$2:$L$2436,MATCH($B$3&"|1|"&E$14&"|"&$A25,'Master Data'!$A$2:$A$2436,0)),"") -> Penuh | X25: =IFERROR(INDEX('Master Data'!$L$2:$L$2436,MATCH($B$3&"|1|"&F$14&"|"&$A25,'Master Data'!$A$2:$A$2436,0)),"") -> Sebagian | Y25: =IFERROR(INDEX('Master Data'!$L$2:$L$2436,MATCH($B$3&"|1|"&G$14&"|"&$A25,'Master Data'!$A$2:$A$2436,0)),"") -> Sebagian | Z25: =IFERROR(INDEX('Master Data'!$L$2:$L$2436,MATCH($B$3&"|1|"&H$14&"|"&$A25,'Master Data'!$A$2:$A$2436,0)),"") -> Sebagian
A26: 17:15 | B26: =IFERROR(INDEX('Master Data'!$M$2:$M$2436,MATCH($B$3&"|1|"&B$14&"|"&$A26,'Master Data'!$A$2:$A$2436,0)),"") -> Baby 2/5 coach: Rischa | C26: =IFERROR(INDEX('Master Data'!$M$2:$M$2436,MATCH($B$3&"|1|"&C$14&"|"&$A26,'Master Data'!$A$2:$A$2436,0)),"") -> Baby 4/5 coach: Danti | D26: =IFERROR(INDEX('Master Data'!$M$2:$M$2436,MATCH($B$3&"|1|"&D$14&"|"&$A26,'Master Data'!$A$2:$A$2436,0)),"") -> (tanpa age group) 0/5 coach: – | E26: =IFERROR(INDEX('Master Data'!$M$2:$M$2436,MATCH($B$3&"|1|"&E$14&"|"&$A26,'Master Data'!$A$2:$A$2436,0)),"") -> (tanpa age group) 0/5 coach: – | F26: =IFERROR(INDEX('Master Data'!$M$2:$M$2436,MATCH($B$3&"|1|"&F$14&"|"&$A26,'Master Data'!$A$2:$A$2436,0)),"") -> Baby 5/5 coach: Nuky | G26: =IFERROR(INDEX('Master Data'!$M$2:$M$2436,MATCH($B$3&"|1|"&G$14&"|"&$A26,'Master Data'!$A$2:$A$2436,0)),"") -> (tanpa age group) 0/5 coach: – | H26: =IFERROR(INDEX('Master Data'!$M$2:$M$2436,MATCH($B$3&"|1|"&H$14&"|"&$A26,'Master Data'!$A$2:$A$2436,0)),"") -> (tanpa age group) 0/5 coach: – | T26: =IFERROR(INDEX('Master Data'!$L$2:$L$2436,MATCH($B$3&"|1|"&B$14&"|"&$A26,'Master Data'!$A$2:$A$2436,0)),"") -> Sebagian | U26: =IFERROR(INDEX('Master Data'!$L$2:$L$2436,MATCH($B$3&"|1|"&C$14&"|"&$A26,'Master Data'!$A$2:$A$2436,0)),"") -> Sebagian | V26: =IFERROR(INDEX('Master Data'!$L$2:$L$2436,MATCH($B$3&"|1|"&D$14&"|"&$A26,'Master Data'!$A$2:$A$2436,0)),"") -> Slot kosong | W26: =IFERROR(INDEX('Master Data'!$L$2:$L$2436,MATCH($B$3&"|1|"&E$14&"|"&$A26,'Master Data'!$A$2:$A$2436,0)),"") -> Slot kosong | X26: =IFERROR(INDEX('Master Data'!$L$2:$L$2436,MATCH($B$3&"|1|"&F$14&"|"&$A26,'Master Data'!$A$2:$A$2436,0)),"") -> Penuh | Y26: =IFERROR(INDEX('Master Data'!$L$2:$L$2436,MATCH($B$3&"|1|"&G$14&"|"&$A26,'Master Data'!$A$2:$A$2436,0)),"") -> Slot kosong | Z26: =IFERROR(INDEX('Master Data'!$L$2:$L$2436,MATCH($B$3&"|1|"&H$14&"|"&$A26,'Master Data'!$A$2:$A$2436,0)),"") -> Slot kosong
A28: LANE 2 | C28: ="Utilisasi lane: "&IFERROR(TEXT(SUMIFS('Master Data'!$H$2:$H$2436,'Master Data'!$B$2:$B$2436,$B$3,'Master Data'!$C$2:$C$2436,2,'Master Data'!$G$2:$G$2436,">0")/SUMIFS('Master Data'!$G$2:$G$2436,'Master Data'!$B$2:$B$2436,$B$3,'Master Data'!$C$2:$C$2436,2,'Master Data'!$G$2:$G$2436,">0"),"0%"),"–")&" · Belum terisi: "&COUNTIFS('Master Data'!$B$2:$B$2436,$B$3,'Master Data'!$C$2:$C$2436,2,'Master Data'!$L$2:$L$2436,"Belum terisi")&" · Slot kosong: "&COUNTIFS('Master Data'!$B$2:$B$2436,$B$3,'Master Data'!$C$2:$C$2436,2,'Master Data'!$L$2:$L$2436,"Slot kosong") -> Utilisasi lane: 48% · Belum terisi: 24 · Slot kosong: 0
A29: Jam | B29: Senin | C29: Selasa | D29: Rabu | E29: Kamis | F29: Jumat | G29: Sabtu | H29: Minggu
A30: 08:15 | B30: =IFERROR(INDEX('Master Data'!$M$2:$M$2436,MATCH($B$3&"|2|"&B$29&"|"&$A30,'Master Data'!$A$2:$A$2436,0)),"") -> Tiny 0/0 coach: – | C30: =IFERROR(INDEX('Master Data'!$M$2:$M$2436,MATCH($B$3&"|2|"&C$29&"|"&$A30,'Master Data'!$A$2:$A$2436,0)),"") -> Tiny 0/0 coach: – | D30: =IFERROR(INDEX('Master Data'!$M$2:$M$2436,MATCH($B$3&"|2|"&D$29&"|"&$A30,'Master Data'!$A$2:$A$2436,0)),"") -> Tiny 0/0 coach: – | E30: =IFERROR(INDEX('Master Data'!$M$2:$M$2436,MATCH($B$3&"|2|"&E$29&"|"&$A30,'Master Data'!$A$2:$A$2436,0)),"") -> Tiny 0/0 coach: – | F30: =IFERROR(INDEX('Master Data'!$M$2:$M$2436,MATCH($B$3&"|2|"&F$29&"|"&$A30,'Master Data'!$A$2:$A$2436,0)),"") -> Tiny 0/0 coach: – | G30: =IFERROR(INDEX('Master Data'!$M$2:$M$2436,MATCH($B$3&"|2|"&G$29&"|"&$A30,'Master Data'!$A$2:$A$2436,0)),"") -> Tiny 0/0 coach: – | H30: =IFERROR(INDEX('Master Data'!$M$2:$M$2436,MATCH($B$3&"|2|"&H$29&"|"&$A30,'Master Data'!$A$2:$A$2436,0)),"") -> Tiny 0/0 coach: – | T30: =IFERROR(INDEX('Master Data'!$L$2:$L$2436,MATCH($B$3&"|2|"&B$29&"|"&$A30,'Master Data'!$A$2:$A$2436,0)),"") -> Tutup | U30: =IFERROR(INDEX('Master Data'!$L$2:$L$2436,MATCH($B$3&"|2|"&C$29&"|"&$A30,'Master Data'!$A$2:$A$2436,0)),"") -> Tutup | V30: =IFERROR(INDEX('Master Data'!$L$2:$L$2436,MATCH($B$3&"|2|"&D$29&"|"&$A30,'Master Data'!$A$2:$A$2436,0)),"") -> Tutup | W30: =IFERROR(INDEX('Master Data'!$L$2:$L$2436,MATCH($B$3&"|2|"&E$29&"|"&$A30,'Master Data'!$A$2:$A$2436,0)),"") -> Tutup | X30: =IFERROR(INDEX('Master Data'!$L$2:$L$2436,MATCH($B$3&"|2|"&F$29&"|"&$A30,'Master Data'!$A$2:$A$2436,0)),"") -> Tutup | Y30: =IFERROR(INDEX('Master Data'!$L$2:$L$2436,MATCH($B$3&"|2|"&G$29&"|"&$A30,'Master Data'!$A$2:$A$2436,0)),"") -> Tutup | Z30: =IFERROR(INDEX('Master Data'!$L$2:$L$2436,MATCH($B$3&"|2|"&H$29&"|"&$A30,'Master Data'!$A$2:$A$2436,0)),"") -> Tutup
A31: 09:00 | B31: =IFERROR(INDEX('Master Data'!$M$2:$M$2436,MATCH($B$3&"|2|"&B$29&"|"&$A31,'Master Data'!$A$2:$A$2436,0)),"") -> Tiny 3/5 coach: Zidane | C31: =IFERROR(INDEX('Master Data'!$M$2:$M$2436,MATCH($B$3&"|2|"&C$29&"|"&$A31,'Master Data'!$A$2:$A$2436,0)),"") -> Tiny 5/5 coach: Zidane | D31: =IFERROR(INDEX('Master Data'!$M$2:$M$2436,MATCH($B$3&"|2|"&D$29&"|"&$A31,'Master Data'!$A$2:$A$2436,0)),"") -> Tiny 4/5 coach: Eka | E31: =IFERROR(INDEX('Master Data'!$M$2:$M$2436,MATCH($B$3&"|2|"&E$29&"|"&$A31,'Master Data'!$A$2:$A$2436,0)),"") -> Tiny 0/5 coach: – | F31: =IFERROR(INDEX('Master Data'!$M$2:$M$2436,MATCH($B$3&"|2|"&F$29&"|"&$A31,'Master Data'!$A$2:$A$2436,0)),"") -> Tiny 2/5 coach: Gita | G31: =IFERROR(INDEX('Master Data'!$M$2:$M$2436,MATCH($B$3&"|2|"&G$29&"|"&$A31,'Master Data'!$A$2:$A$2436,0)),"") -> Tiny 5/5 coach: Rischa | H31: =IFERROR(INDEX('Master Data'!$M$2:$M$2436,MATCH($B$3&"|2|"&H$29&"|"&$A31,'Master Data'!$A$2:$A$2436,0)),"") -> Tiny 5/5 coach: Danti | T31: =IFERROR(INDEX('Master Data'!$L$2:$L$2436,MATCH($B$3&"|2|"&B$29&"|"&$A31,'Master Data'!$A$2:$A$2436,0)),"") -> Sebagian | U31: =IFERROR(INDEX('Master Data'!$L$2:$L$2436,MATCH($B$3&"|2|"&C$29&"|"&$A31,'Master Data'!$A$2:$A$2436,0)),"") -> Penuh | V31: =IFERROR(INDEX('Master Data'!$L$2:$L$2436,MATCH($B$3&"|2|"&D$29&"|"&$A31,'Master Data'!$A$2:$A$2436,0)),"") -> Sebagian | W31: =IFERROR(INDEX('Master Data'!$L$2:$L$2436,MATCH($B$3&"|2|"&E$29&"|"&$A31,'Master Data'!$A$2:$A$2436,0)),"") -> Belum terisi | X31: =IFERROR(INDEX('Master Data'!$L$2:$L$2436,MATCH($B$3&"|2|"&F$29&"|"&$A31,'Master Data'!$A$2:$A$2436,0)),"") -> Sebagian | Y31: =IFERROR(INDEX('Master Data'!$L$2:$L$2436,MATCH($B$3&"|2|"&G$29&"|"&$A31,'Master Data'!$A$2:$A$2436,0)),"") -> Penuh | Z31: =IFERROR(INDEX('Master Data'!$L$2:$L$2436,MATCH($B$3&"|2|"&H$29&"|"&$A31,'Master Data'!$A$2:$A$2436,0)),"") -> Penuh
A32: 09:45 | B32: =IFERROR(INDEX('Master Data'!$M$2:$M$2436,MATCH($B$3&"|2|"&B$29&"|"&$A32,'Master Data'!$A$2:$A$2436,0)),"") -> Tiny 3/5 coach: Zidane | C32: =IFERROR(INDEX('Master Data'!$M$2:$M$2436,MATCH($B$3&"|2|"&C$29&"|"&$A32,'Master Data'!$A$2:$A$2436,0)),"") -> Tiny 4/5 coach: Rischa | D32: =IFERROR(INDEX('Master Data'!$M$2:$M$2436,MATCH($B$3&"|2|"&D$29&"|"&$A32,'Master Data'!$A$2:$A$2436,0)),"") -> Tiny 4/5 coach: Surya | E32: =IFERROR(INDEX('Master Data'!$M$2:$M$2436,MATCH($B$3&"|2|"&E$29&"|"&$A32,'Master Data'!$A$2:$A$2436,0)),"") -> Tiny 4/5 coach: Eka | F32: =IFERROR(INDEX('Master Data'!$M$2:$M$2436,MATCH($B$3&"|2|"&F$29&"|"&$A32,'Master Data'!$A$2:$A$2436,0)),"") -> Tiny 5/5 coach: Surya | G32: =IFERROR(INDEX('Master Data'!$M$2:$M$2436,MATCH($B$3&"|2|"&G$29&"|"&$A32,'Master Data'!$A$2:$A$2436,0)),"") -> Tiny 5/5 coach: Eka | H32: =IFERROR(INDEX('Master Data'!$M$2:$M$2436,MATCH($B$3&"|2|"&H$29&"|"&$A32,'Master Data'!$A$2:$A$2436,0)),"") -> Tiny 4/5 coach: Rischa | T32: =IFERROR(INDEX('Master Data'!$L$2:$L$2436,MATCH($B$3&"|2|"&B$29&"|"&$A32,'Master Data'!$A$2:$A$2436,0)),"") -> Sebagian | U32: =IFERROR(INDEX('Master Data'!$L$2:$L$2436,MATCH($B$3&"|2|"&C$29&"|"&$A32,'Master Data'!$A$2:$A$2436,0)),"") -> Sebagian | V32: =IFERROR(INDEX('Master Data'!$L$2:$L$2436,MATCH($B$3&"|2|"&D$29&"|"&$A32,'Master Data'!$A$2:$A$2436,0)),"") -> Sebagian | W32: =IFERROR(INDEX('Master Data'!$L$2:$L$2436,MATCH($B$3&"|2|"&E$29&"|"&$A32,'Master Data'!$A$2:$A$2436,0)),"") -> Sebagian | X32: =IFERROR(INDEX('Master Data'!$L$2:$L$2436,MATCH($B$3&"|2|"&F$29&"|"&$A32,'Master Data'!$A$2:$A$2436,0)),"") -> Penuh | Y32: =IFERROR(INDEX('Master Data'!$L$2:$L$2436,MATCH($B$3&"|2|"&G$29&"|"&$A32,'Master Data'!$A$2:$A$2436,0)),"") -> Penuh | Z32: =IFERROR(INDEX('Master Data'!$L$2:$L$2436,MATCH($B$3&"|2|"&H$29&"|"&$A32,'Master Data'!$A$2:$A$2436,0)),"") -> Sebagian
A33: 10:30 | B33: =IFERROR(INDEX('Master Data'!$M$2:$M$2436,MATCH($B$3&"|2|"&B$29&"|"&$A33,'Master Data'!$A$2:$A$2436,0)),"") -> Tiny 0/5 coach: – | C33: =IFERROR(INDEX('Master Data'!$M$2:$M$2436,MATCH($B$3&"|2|"&C$29&"|"&$A33,'Master Data'!$A$2:$A$2436,0)),"") -> Tiny 3/5 coach: Rischa | D33: =IFERROR(INDEX('Master Data'!$M$2:$M$2436,MATCH($B$3&"|2|"&D$29&"|"&$A33,'Master Data'!$A$2:$A$2436,0)),"") -> Tiny 5/5 coach: Surya | E33: =IFERROR(INDEX('Master Data'!$M$2:$M$2436,MATCH($B$3&"|2|"&E$29&"|"&$A33,'Master Data'!$A$2:$A$2436,0)),"") -> Tiny 0/5 coach: – | F33: =IFERROR(INDEX('Master Data'!$M$2:$M$2436,MATCH($B$3&"|2|"&F$29&"|"&$A33,'Master Data'!$A$2:$A$2436,0)),"") -> Tiny 0/5 coach: – | G33: =IFERROR(INDEX('Master Data'!$M$2:$M$2436,MATCH($B$3&"|2|"&G$29&"|"&$A33,'Master Data'!$A$2:$A$2436,0)),"") -> Tiny 5/5 coach: Eka | H33: =IFERROR(INDEX('Master Data'!$M$2:$M$2436,MATCH($B$3&"|2|"&H$29&"|"&$A33,'Master Data'!$A$2:$A$2436,0)),"") -> Tiny 5/5 coach: Danti | T33: =IFERROR(INDEX('Master Data'!$L$2:$L$2436,MATCH($B$3&"|2|"&B$29&"|"&$A33,'Master Data'!$A$2:$A$2436,0)),"") -> Belum terisi | U33: =IFERROR(INDEX('Master Data'!$L$2:$L$2436,MATCH($B$3&"|2|"&C$29&"|"&$A33,'Master Data'!$A$2:$A$2436,0)),"") -> Sebagian | V33: =IFERROR(INDEX('Master Data'!$L$2:$L$2436,MATCH($B$3&"|2|"&D$29&"|"&$A33,'Master Data'!$A$2:$A$2436,0)),"") -> Penuh | W33: =IFERROR(INDEX('Master Data'!$L$2:$L$2436,MATCH($B$3&"|2|"&E$29&"|"&$A33,'Master Data'!$A$2:$A$2436,0)),"") -> Belum terisi | X33: =IFERROR(INDEX('Master Data'!$L$2:$L$2436,MATCH($B$3&"|2|"&F$29&"|"&$A33,'Master Data'!$A$2:$A$2436,0)),"") -> Belum terisi | Y33: =IFERROR(INDEX('Master Data'!$L$2:$L$2436,MATCH($B$3&"|2|"&G$29&"|"&$A33,'Master Data'!$A$2:$A$2436,0)),"") -> Penuh | Z33: =IFERROR(INDEX('Master Data'!$L$2:$L$2436,MATCH($B$3&"|2|"&H$29&"|"&$A33,'Master Data'!$A$2:$A$2436,0)),"") -> Penuh
A34: 11:15 | B34: =IFERROR(INDEX('Master Data'!$M$2:$M$2436,MATCH($B$3&"|2|"&B$29&"|"&$A34,'Master Data'!$A$2:$A$2436,0)),"") -> Tiny 0/5 coach: – | C34: =IFERROR(INDEX('Master Data'!$M$2:$M$2436,MATCH($B$3&"|2|"&C$29&"|"&$A34,'Master Data'!$A$2:$A$2436,0)),"") -> Tiny 0/5 coach: – | D34: =IFERROR(INDEX('Master Data'!$M$2:$M$2436,MATCH($B$3&"|2|"&D$29&"|"&$A34,'Master Data'!$A$2:$A$2436,0)),"") -> Tiny 0/5 coach: – | E34: =IFERROR(INDEX('Master Data'!$M$2:$M$2436,MATCH($B$3&"|2|"&E$29&"|"&$A34,'Master Data'!$A$2:$A$2436,0)),"") -> Tiny 0/5 coach: – | F34: =IFERROR(INDEX('Master Data'!$M$2:$M$2436,MATCH($B$3&"|2|"&F$29&"|"&$A34,'Master Data'!$A$2:$A$2436,0)),"") -> Tiny 0/5 coach: – | G34: =IFERROR(INDEX('Master Data'!$M$2:$M$2436,MATCH($B$3&"|2|"&G$29&"|"&$A34,'Master Data'!$A$2:$A$2436,0)),"") -> Tiny 4/5 coach: Nuky | H34: =IFERROR(INDEX('Master Data'!$M$2:$M$2436,MATCH($B$3&"|2|"&H$29&"|"&$A34,'Master Data'!$A$2:$A$2436,0)),"") -> Tiny 5/5 coach: Surya | T34: =IFERROR(INDEX('Master Data'!$L$2:$L$2436,MATCH($B$3&"|2|"&B$29&"|"&$A34,'Master Data'!$A$2:$A$2436,0)),"") -> Belum terisi | U34: =IFERROR(INDEX('Master Data'!$L$2:$L$2436,MATCH($B$3&"|2|"&C$29&"|"&$A34,'Master Data'!$A$2:$A$2436,0)),"") -> Belum terisi | V34: =IFERROR(INDEX('Master Data'!$L$2:$L$2436,MATCH($B$3&"|2|"&D$29&"|"&$A34,'Master Data'!$A$2:$A$2436,0)),"") -> Belum terisi | W34: =IFERROR(INDEX('Master Data'!$L$2:$L$2436,MATCH($B$3&"|2|"&E$29&"|"&$A34,'Master Data'!$A$2:$A$2436,0)),"") -> Belum terisi | X34: =IFERROR(INDEX('Master Data'!$L$2:$L$2436,MATCH($B$3&"|2|"&F$29&"|"&$A34,'Master Data'!$A$2:$A$2436,0)),"") -> Belum terisi | Y34: =IFERROR(INDEX('Master Data'!$L$2:$L$2436,MATCH($B$3&"|2|"&G$29&"|"&$A34,'Master Data'!$A$2:$A$2436,0)),"") -> Sebagian | Z34: =IFERROR(INDEX('Master Data'!$L$2:$L$2436,MATCH($B$3&"|2|"&H$29&"|"&$A34,'Master Data'!$A$2:$A$2436,0)),"") -> Penuh
A35: 12:00 | B35: =IFERROR(INDEX('Master Data'!$M$2:$M$2436,MATCH($B$3&"|2|"&B$29&"|"&$A35,'Master Data'!$A$2:$A$2436,0)),"") -> Tiny 0/0 coach: – | C35: =IFERROR(INDEX('Master Data'!$M$2:$M$2436,MATCH($B$3&"|2|"&C$29&"|"&$A35,'Master Data'!$A$2:$A$2436,0)),"") -> Tiny 0/0 coach: – | D35: =IFERROR(INDEX('Master Data'!$M$2:$M$2436,MATCH($B$3&"|2|"&D$29&"|"&$A35,'Master Data'!$A$2:$A$2436,0)),"") -> Tiny 0/0 coach: – | E35: =IFERROR(INDEX('Master Data'!$M$2:$M$2436,MATCH($B$3&"|2|"&E$29&"|"&$A35,'Master Data'!$A$2:$A$2436,0)),"") -> Tiny 0/0 coach: – | F35: =IFERROR(INDEX('Master Data'!$M$2:$M$2436,MATCH($B$3&"|2|"&F$29&"|"&$A35,'Master Data'!$A$2:$A$2436,0)),"") -> Tiny 0/0 coach: – | G35: =IFERROR(INDEX('Master Data'!$M$2:$M$2436,MATCH($B$3&"|2|"&G$29&"|"&$A35,'Master Data'!$A$2:$A$2436,0)),"") -> Kids 4/4 coach: Tessa | H35: =IFERROR(INDEX('Master Data'!$M$2:$M$2436,MATCH($B$3&"|2|"&H$29&"|"&$A35,'Master Data'!$A$2:$A$2436,0)),"") -> Tiny 2/5 coach: Tessa | T35: =IFERROR(INDEX('Master Data'!$L$2:$L$2436,MATCH($B$3&"|2|"&B$29&"|"&$A35,'Master Data'!$A$2:$A$2436,0)),"") -> Tutup | U35: =IFERROR(INDEX('Master Data'!$L$2:$L$2436,MATCH($B$3&"|2|"&C$29&"|"&$A35,'Master Data'!$A$2:$A$2436,0)),"") -> Tutup | V35: =IFERROR(INDEX('Master Data'!$L$2:$L$2436,MATCH($B$3&"|2|"&D$29&"|"&$A35,'Master Data'!$A$2:$A$2436,0)),"") -> Tutup | W35: =IFERROR(INDEX('Master Data'!$L$2:$L$2436,MATCH($B$3&"|2|"&E$29&"|"&$A35,'Master Data'!$A$2:$A$2436,0)),"") -> Tutup | X35: =IFERROR(INDEX('Master Data'!$L$2:$L$2436,MATCH($B$3&"|2|"&F$29&"|"&$A35,'Master Data'!$A$2:$A$2436,0)),"") -> Tutup | Y35: =IFERROR(INDEX('Master Data'!$L$2:$L$2436,MATCH($B$3&"|2|"&G$29&"|"&$A35,'Master Data'!$A$2:$A$2436,0)),"") -> Penuh | Z35: =IFERROR(INDEX('Master Data'!$L$2:$L$2436,MATCH($B$3&"|2|"&H$29&"|"&$A35,'Master Data'!$A$2:$A$2436,0)),"") -> Sebagian
A36: 13:30 | B36: =IFERROR(INDEX('Master Data'!$M$2:$M$2436,MATCH($B$3&"|2|"&B$29&"|"&$A36,'Master Data'!$A$2:$A$2436,0)),"") -> Tiny 0/5 coach: – | C36: =IFERROR(INDEX('Master Data'!$M$2:$M$2436,MATCH($B$3&"|2|"&C$29&"|"&$A36,'Master Data'!$A$2:$A$2436,0)),"") -> Tiny 0/5 coach: – | D36: =IFERROR(INDEX('Master Data'!$M$2:$M$2436,MATCH($B$3&"|2|"&D$29&"|"&$A36,'Master Data'!$A$2:$A$2436,0)),"") -> Tiny 0/5 coach: – | E36: =IFERROR(INDEX('Master Data'!$M$2:$M$2436,MATCH($B$3&"|2|"&E$29&"|"&$A36,'Master Data'!$A$2:$A$2436,0)),"") -> Tiny 0/5 coach: – | F36: =IFERROR(INDEX('Master Data'!$M$2:$M$2436,MATCH($B$3&"|2|"&F$29&"|"&$A36,'Master Data'!$A$2:$A$2436,0)),"") -> Tiny 0/5 coach: – | G36: =IFERROR(INDEX('Master Data'!$M$2:$M$2436,MATCH($B$3&"|2|"&G$29&"|"&$A36,'Master Data'!$A$2:$A$2436,0)),"") -> Tiny 3/5 coach: Zidane | H36: =IFERROR(INDEX('Master Data'!$M$2:$M$2436,MATCH($B$3&"|2|"&H$29&"|"&$A36,'Master Data'!$A$2:$A$2436,0)),"") -> Tiny 4/5 coach: Surya | T36: =IFERROR(INDEX('Master Data'!$L$2:$L$2436,MATCH($B$3&"|2|"&B$29&"|"&$A36,'Master Data'!$A$2:$A$2436,0)),"") -> Belum terisi | U36: =IFERROR(INDEX('Master Data'!$L$2:$L$2436,MATCH($B$3&"|2|"&C$29&"|"&$A36,'Master Data'!$A$2:$A$2436,0)),"") -> Belum terisi | V36: =IFERROR(INDEX('Master Data'!$L$2:$L$2436,MATCH($B$3&"|2|"&D$29&"|"&$A36,'Master Data'!$A$2:$A$2436,0)),"") -> Belum terisi | W36: =IFERROR(INDEX('Master Data'!$L$2:$L$2436,MATCH($B$3&"|2|"&E$29&"|"&$A36,'Master Data'!$A$2:$A$2436,0)),"") -> Belum terisi | X36: =IFERROR(INDEX('Master Data'!$L$2:$L$2436,MATCH($B$3&"|2|"&F$29&"|"&$A36,'Master Data'!$A$2:$A$2436,0)),"") -> Belum terisi | Y36: =IFERROR(INDEX('Master Data'!$L$2:$L$2436,MATCH($B$3&"|2|"&G$29&"|"&$A36,'Master Data'!$A$2:$A$2436,0)),"") -> Sebagian | Z36: =IFERROR(INDEX('Master Data'!$L$2:$L$2436,MATCH($B$3&"|2|"&H$29&"|"&$A36,'Master Data'!$A$2:$A$2436,0)),"") -> Sebagian
A37: 14:15 | B37: =IFERROR(INDEX('Master Data'!$M$2:$M$2436,MATCH($B$3&"|2|"&B$29&"|"&$A37,'Master Data'!$A$2:$A$2436,0)),"") -> Tiny 1/5 coach: Rischa | C37: =IFERROR(INDEX('Master Data'!$M$2:$M$2436,MATCH($B$3&"|2|"&C$29&"|"&$A37,'Master Data'!$A$2:$A$2436,0)),"") -> Tiny 2/5 coach: Rischa | D37: =IFERROR(INDEX('Master Data'!$M$2:$M$2436,MATCH($B$3&"|2|"&D$29&"|"&$A37,'Master Data'!$A$2:$A$2436,0)),"") -> Tiny 0/5 coach: – | E37: =IFERROR(INDEX('Master Data'!$M$2:$M$2436,MATCH($B$3&"|2|"&E$29&"|"&$A37,'Master Data'!$A$2:$A$2436,0)),"") -> Tiny 0/5 coach: – | F37: =IFERROR(INDEX('Master Data'!$M$2:$M$2436,MATCH($B$3&"|2|"&F$29&"|"&$A37,'Master Data'!$A$2:$A$2436,0)),"") -> Tiny 3/5 coach: Surya | G37: =IFERROR(INDEX('Master Data'!$M$2:$M$2436,MATCH($B$3&"|2|"&G$29&"|"&$A37,'Master Data'!$A$2:$A$2436,0)),"") -> Tiny 5/5 coach: Rischa | H37: =IFERROR(INDEX('Master Data'!$M$2:$M$2436,MATCH($B$3&"|2|"&H$29&"|"&$A37,'Master Data'!$A$2:$A$2436,0)),"") -> Kids 1/4 coach: Tessa | T37: =IFERROR(INDEX('Master Data'!$L$2:$L$2436,MATCH($B$3&"|2|"&B$29&"|"&$A37,'Master Data'!$A$2:$A$2436,0)),"") -> Sebagian | U37: =IFERROR(INDEX('Master Data'!$L$2:$L$2436,MATCH($B$3&"|2|"&C$29&"|"&$A37,'Master Data'!$A$2:$A$2436,0)),"") -> Sebagian | V37: =IFERROR(INDEX('Master Data'!$L$2:$L$2436,MATCH($B$3&"|2|"&D$29&"|"&$A37,'Master Data'!$A$2:$A$2436,0)),"") -> Belum terisi | W37: =IFERROR(INDEX('Master Data'!$L$2:$L$2436,MATCH($B$3&"|2|"&E$29&"|"&$A37,'Master Data'!$A$2:$A$2436,0)),"") -> Belum terisi | X37: =IFERROR(INDEX('Master Data'!$L$2:$L$2436,MATCH($B$3&"|2|"&F$29&"|"&$A37,'Master Data'!$A$2:$A$2436,0)),"") -> Sebagian | Y37: =IFERROR(INDEX('Master Data'!$L$2:$L$2436,MATCH($B$3&"|2|"&G$29&"|"&$A37,'Master Data'!$A$2:$A$2436,0)),"") -> Penuh | Z37: =IFERROR(INDEX('Master Data'!$L$2:$L$2436,MATCH($B$3&"|2|"&H$29&"|"&$A37,'Master Data'!$A$2:$A$2436,0)),"") -> Sebagian
A38: 15:00 | B38: =IFERROR(INDEX('Master Data'!$M$2:$M$2436,MATCH($B$3&"|2|"&B$29&"|"&$A38,'Master Data'!$A$2:$A$2436,0)),"") -> Tiny 0/0 coach: – | C38: =IFERROR(INDEX('Master Data'!$M$2:$M$2436,MATCH($B$3&"|2|"&C$29&"|"&$A38,'Master Data'!$A$2:$A$2436,0)),"") -> Tiny 0/0 coach: – | D38: =IFERROR(INDEX('Master Data'!$M$2:$M$2436,MATCH($B$3&"|2|"&D$29&"|"&$A38,'Master Data'!$A$2:$A$2436,0)),"") -> Tiny 0/0 coach: – | E38: =IFERROR(INDEX('Master Data'!$M$2:$M$2436,MATCH($B$3&"|2|"&E$29&"|"&$A38,'Master Data'!$A$2:$A$2436,0)),"") -> Tiny 0/0 coach: – | F38: =IFERROR(INDEX('Master Data'!$M$2:$M$2436,MATCH($B$3&"|2|"&F$29&"|"&$A38,'Master Data'!$A$2:$A$2436,0)),"") -> Tiny 0/0 coach: – | G38: =IFERROR(INDEX('Master Data'!$M$2:$M$2436,MATCH($B$3&"|2|"&G$29&"|"&$A38,'Master Data'!$A$2:$A$2436,0)),"") -> Tiny 5/5 coach: Nuky | H38: =IFERROR(INDEX('Master Data'!$M$2:$M$2436,MATCH($B$3&"|2|"&H$29&"|"&$A38,'Master Data'!$A$2:$A$2436,0)),"") -> Tiny 3/5 coach: Nuky | T38: =IFERROR(INDEX('Master Data'!$L$2:$L$2436,MATCH($B$3&"|2|"&B$29&"|"&$A38,'Master Data'!$A$2:$A$2436,0)),"") -> Tutup | U38: =IFERROR(INDEX('Master Data'!$L$2:$L$2436,MATCH($B$3&"|2|"&C$29&"|"&$A38,'Master Data'!$A$2:$A$2436,0)),"") -> Tutup | V38: =IFERROR(INDEX('Master Data'!$L$2:$L$2436,MATCH($B$3&"|2|"&D$29&"|"&$A38,'Master Data'!$A$2:$A$2436,0)),"") -> Tutup | W38: =IFERROR(INDEX('Master Data'!$L$2:$L$2436,MATCH($B$3&"|2|"&E$29&"|"&$A38,'Master Data'!$A$2:$A$2436,0)),"") -> Tutup | X38: =IFERROR(INDEX('Master Data'!$L$2:$L$2436,MATCH($B$3&"|2|"&F$29&"|"&$A38,'Master Data'!$A$2:$A$2436,0)),"") -> Tutup | Y38: =IFERROR(INDEX('Master Data'!$L$2:$L$2436,MATCH($B$3&"|2|"&G$29&"|"&$A38,'Master Data'!$A$2:$A$2436,0)),"") -> Penuh | Z38: =IFERROR(INDEX('Master Data'!$L$2:$L$2436,MATCH($B$3&"|2|"&H$29&"|"&$A38,'Master Data'!$A$2:$A$2436,0)),"") -> Sebagian
A39: 15:45 | B39: =IFERROR(INDEX('Master Data'!$M$2:$M$2436,MATCH($B$3&"|2|"&B$29&"|"&$A39,'Master Data'!$A$2:$A$2436,0)),"") -> Tiny 0/0 coach: – | C39: =IFERROR(INDEX('Master Data'!$M$2:$M$2436,MATCH($B$3&"|2|"&C$29&"|"&$A39,'Master Data'!$A$2:$A$2436,0)),"") -> Kids 4/0 coach: Dian | D39: =IFERROR(INDEX('Master Data'!$M$2:$M$2436,MATCH($B$3&"|2|"&D$29&"|"&$A39,'Master Data'!$A$2:$A$2436,0)),"") -> Tiny 0/5 coach: – | E39: =IFERROR(INDEX('Master Data'!$M$2:$M$2436,MATCH($B$3&"|2|"&E$29&"|"&$A39,'Master Data'!$A$2:$A$2436,0)),"") -> Tiny 0/0 coach: – | F39: =IFERROR(INDEX('Master Data'!$M$2:$M$2436,MATCH($B$3&"|2|"&F$29&"|"&$A39,'Master Data'!$A$2:$A$2436,0)),"") -> Kids 4/0 coach: Tessa | G39: =IFERROR(INDEX('Master Data'!$M$2:$M$2436,MATCH($B$3&"|2|"&G$29&"|"&$A39,'Master Data'!$A$2:$A$2436,0)),"") -> Kids 4/4 coach: Gita | H39: =IFERROR(INDEX('Master Data'!$M$2:$M$2436,MATCH($B$3&"|2|"&H$29&"|"&$A39,'Master Data'!$A$2:$A$2436,0)),"") -> Tiny 5/5 coach: Gita | T39: =IFERROR(INDEX('Master Data'!$L$2:$L$2436,MATCH($B$3&"|2|"&B$29&"|"&$A39,'Master Data'!$A$2:$A$2436,0)),"") -> Tutup | U39: =IFERROR(INDEX('Master Data'!$L$2:$L$2436,MATCH($B$3&"|2|"&C$29&"|"&$A39,'Master Data'!$A$2:$A$2436,0)),"") -> Lebih kapasitas | V39: =IFERROR(INDEX('Master Data'!$L$2:$L$2436,MATCH($B$3&"|2|"&D$29&"|"&$A39,'Master Data'!$A$2:$A$2436,0)),"") -> Belum terisi | W39: =IFERROR(INDEX('Master Data'!$L$2:$L$2436,MATCH($B$3&"|2|"&E$29&"|"&$A39,'Master Data'!$A$2:$A$2436,0)),"") -> Tutup | X39: =IFERROR(INDEX('Master Data'!$L$2:$L$2436,MATCH($B$3&"|2|"&F$29&"|"&$A39,'Master Data'!$A$2:$A$2436,0)),"") -> Lebih kapasitas | Y39: =IFERROR(INDEX('Master Data'!$L$2:$L$2436,MATCH($B$3&"|2|"&G$29&"|"&$A39,'Master Data'!$A$2:$A$2436,0)),"") -> Penuh | Z39: =IFERROR(INDEX('Master Data'!$L$2:$L$2436,MATCH($B$3&"|2|"&H$29&"|"&$A39,'Master Data'!$A$2:$A$2436,0)),"") -> Penuh
A40: 16:30 | B40: =IFERROR(INDEX('Master Data'!$M$2:$M$2436,MATCH($B$3&"|2|"&B$29&"|"&$A40,'Master Data'!$A$2:$A$2436,0)),"") -> Tiny 0/5 coach: – | C40: =IFERROR(INDEX('Master Data'!$M$2:$M$2436,MATCH($B$3&"|2|"&C$29&"|"&$A40,'Master Data'!$A$2:$A$2436,0)),"") -> Tiny 3/5 coach: Zidane | D40: =IFERROR(INDEX('Master Data'!$M$2:$M$2436,MATCH($B$3&"|2|"&D$29&"|"&$A40,'Master Data'!$A$2:$A$2436,0)),"") -> Tiny 5/5 coach: Nuky | E40: =IFERROR(INDEX('Master Data'!$M$2:$M$2436,MATCH($B$3&"|2|"&E$29&"|"&$A40,'Master Data'!$A$2:$A$2436,0)),"") -> Tiny 0/5 coach: – | F40: =IFERROR(INDEX('Master Data'!$M$2:$M$2436,MATCH($B$3&"|2|"&F$29&"|"&$A40,'Master Data'!$A$2:$A$2436,0)),"") -> Tiny 4/5 coach: Surya | G40: =IFERROR(INDEX('Master Data'!$M$2:$M$2436,MATCH($B$3&"|2|"&G$29&"|"&$A40,'Master Data'!$A$2:$A$2436,0)),"") -> Tiny 5/5 coach: Tessa | H40: =IFERROR(INDEX('Master Data'!$M$2:$M$2436,MATCH($B$3&"|2|"&H$29&"|"&$A40,'Master Data'!$A$2:$A$2436,0)),"") -> Tiny 5/5 coach: Nuky | T40: =IFERROR(INDEX('Master Data'!$L$2:$L$2436,MATCH($B$3&"|2|"&B$29&"|"&$A40,'Master Data'!$A$2:$A$2436,0)),"") -> Belum terisi | U40: =IFERROR(INDEX('Master Data'!$L$2:$L$2436,MATCH($B$3&"|2|"&C$29&"|"&$A40,'Master Data'!$A$2:$A$2436,0)),"") -> Sebagian | V40: =IFERROR(INDEX('Master Data'!$L$2:$L$2436,MATCH($B$3&"|2|"&D$29&"|"&$A40,'Master Data'!$A$2:$A$2436,0)),"") -> Penuh | W40: =IFERROR(INDEX('Master Data'!$L$2:$L$2436,MATCH($B$3&"|2|"&E$29&"|"&$A40,'Master Data'!$A$2:$A$2436,0)),"") -> Belum terisi | X40: =IFERROR(INDEX('Master Data'!$L$2:$L$2436,MATCH($B$3&"|2|"&F$29&"|"&$A40,'Master Data'!$A$2:$A$2436,0)),"") -> Sebagian | Y40: =IFERROR(INDEX('Master Data'!$L$2:$L$2436,MATCH($B$3&"|2|"&G$29&"|"&$A40,'Master Data'!$A$2:$A$2436,0)),"") -> Penuh | Z40: =IFERROR(INDEX('Master Data'!$L$2:$L$2436,MATCH($B$3&"|2|"&H$29&"|"&$A40,'Master Data'!$A$2:$A$2436,0)),"") -> Penuh
A41: 17:15 | B41: =IFERROR(INDEX('Master Data'!$M$2:$M$2436,MATCH($B$3&"|2|"&B$29&"|"&$A41,'Master Data'!$A$2:$A$2436,0)),"") -> Tiny 0/5 coach: – | C41: =IFERROR(INDEX('Master Data'!$M$2:$M$2436,MATCH($B$3&"|2|"&C$29&"|"&$A41,'Master Data'!$A$2:$A$2436,0)),"") -> Tiny 0/5 coach: – | D41: =IFERROR(INDEX('Master Data'!$M$2:$M$2436,MATCH($B$3&"|2|"&D$29&"|"&$A41,'Master Data'!$A$2:$A$2436,0)),"") -> Tiny 4/5 coach: Eka | E41: =IFERROR(INDEX('Master Data'!$M$2:$M$2436,MATCH($B$3&"|2|"&E$29&"|"&$A41,'Master Data'!$A$2:$A$2436,0)),"") -> Tiny 0/5 coach: – | F41: =IFERROR(INDEX('Master Data'!$M$2:$M$2436,MATCH($B$3&"|2|"&F$29&"|"&$A41,'Master Data'!$A$2:$A$2436,0)),"") -> Tiny 3/5 coach: Tessa | G41: =IFERROR(INDEX('Master Data'!$M$2:$M$2436,MATCH($B$3&"|2|"&G$29&"|"&$A41,'Master Data'!$A$2:$A$2436,0)),"") -> Tiny 0/5 coach: – | H41: =IFERROR(INDEX('Master Data'!$M$2:$M$2436,MATCH($B$3&"|2|"&H$29&"|"&$A41,'Master Data'!$A$2:$A$2436,0)),"") -> Tiny 0/5 coach: – | T41: =IFERROR(INDEX('Master Data'!$L$2:$L$2436,MATCH($B$3&"|2|"&B$29&"|"&$A41,'Master Data'!$A$2:$A$2436,0)),"") -> Belum terisi | U41: =IFERROR(INDEX('Master Data'!$L$2:$L$2436,MATCH($B$3&"|2|"&C$29&"|"&$A41,'Master Data'!$A$2:$A$2436,0)),"") -> Belum terisi | V41: =IFERROR(INDEX('Master Data'!$L$2:$L$2436,MATCH($B$3&"|2|"&D$29&"|"&$A41,'Master Data'!$A$2:$A$2436,0)),"") -> Sebagian | W41: =IFERROR(INDEX('Master Data'!$L$2:$L$2436,MATCH($B$3&"|2|"&E$29&"|"&$A41,'Master Data'!$A$2:$A$2436,0)),"") -> Belum terisi | X41: =IFERROR(INDEX('Master Data'!$L$2:$L$2436,MATCH($B$3&"|2|"&F$29&"|"&$A41,'Master Data'!$A$2:$A$2436,0)),"") -> Sebagian | Y41: =IFERROR(INDEX('Master Data'!$L$2:$L$2436,MATCH($B$3&"|2|"&G$29&"|"&$A41,'Master Data'!$A$2:$A$2436,0)),"") -> Belum terisi | Z41: =IFERROR(INDEX('Master Data'!$L$2:$L$2436,MATCH($B$3&"|2|"&H$29&"|"&$A41,'Master Data'!$A$2:$A$2436,0)),"") -> Belum terisi
A43: LANE 3 | C43: ="Utilisasi lane: "&IFERROR(TEXT(SUMIFS('Master Data'!$H$2:$H$2436,'Master Data'!$B$2:$B$2436,$B$3,'Master Data'!$C$2:$C$2436,3,'Master Data'!$G$2:$G$2436,">0")/SUMIFS('Master Data'!$G$2:$G$2436,'Master Data'!$B$2:$B$2436,$B$3,'Master Data'!$C$2:$C$2436,3,'Master Data'!$G$2:$G$2436,">0"),"0%"),"–")&" · Belum terisi: "&COUNTIFS('Master Data'!$B$2:$B$2436,$B$3,'Master Data'!$C$2:$C$2436,3,'Master Data'!$L$2:$L$2436,"Belum terisi")&" · Slot kosong: "&COUNTIFS('Master Data'!$B$2:$B$2436,$B$3,'Master Data'!$C$2:$C$2436,3,'Master Data'!$L$2:$L$2436,"Slot kosong") -> Utilisasi lane: 77% · Belum terisi: 6 · Slot kosong: 0
A44: Jam | B44: Senin | C44: Selasa | D44: Rabu | E44: Kamis | F44: Jumat | G44: Sabtu | H44: Minggu
A45: 08:00 | B45: =IFERROR(INDEX('Master Data'!$M$2:$M$2436,MATCH($B$3&"|3|"&B$44&"|"&$A45,'Master Data'!$A$2:$A$2436,0)),"") -> Little 0/0 coach: – | C45: =IFERROR(INDEX('Master Data'!$M$2:$M$2436,MATCH($B$3&"|3|"&C$44&"|"&$A45,'Master Data'!$A$2:$A$2436,0)),"") -> Little 0/0 coach: – | D45: =IFERROR(INDEX('Master Data'!$M$2:$M$2436,MATCH($B$3&"|3|"&D$44&"|"&$A45,'Master Data'!$A$2:$A$2436,0)),"") -> Little 0/0 coach: – | E45: =IFERROR(INDEX('Master Data'!$M$2:$M$2436,MATCH($B$3&"|3|"&E$44&"|"&$A45,'Master Data'!$A$2:$A$2436,0)),"") -> Little 0/0 coach: – | F45: =IFERROR(INDEX('Master Data'!$M$2:$M$2436,MATCH($B$3&"|3|"&F$44&"|"&$A45,'Master Data'!$A$2:$A$2436,0)),"") -> Little 0/0 coach: – | G45: =IFERROR(INDEX('Master Data'!$M$2:$M$2436,MATCH($B$3&"|3|"&G$44&"|"&$A45,'Master Data'!$A$2:$A$2436,0)),"") -> Little 0/0 coach: – | H45: =IFERROR(INDEX('Master Data'!$M$2:$M$2436,MATCH($B$3&"|3|"&H$44&"|"&$A45,'Master Data'!$A$2:$A$2436,0)),"") -> Little 0/0 coach: – | T45: =IFERROR(INDEX('Master Data'!$L$2:$L$2436,MATCH($B$3&"|3|"&B$44&"|"&$A45,'Master Data'!$A$2:$A$2436,0)),"") -> Tutup | U45: =IFERROR(INDEX('Master Data'!$L$2:$L$2436,MATCH($B$3&"|3|"&C$44&"|"&$A45,'Master Data'!$A$2:$A$2436,0)),"") -> Tutup | V45: =IFERROR(INDEX('Master Data'!$L$2:$L$2436,MATCH($B$3&"|3|"&D$44&"|"&$A45,'Master Data'!$A$2:$A$2436,0)),"") -> Tutup | W45: =IFERROR(INDEX('Master Data'!$L$2:$L$2436,MATCH($B$3&"|3|"&E$44&"|"&$A45,'Master Data'!$A$2:$A$2436,0)),"") -> Tutup | X45: =IFERROR(INDEX('Master Data'!$L$2:$L$2436,MATCH($B$3&"|3|"&F$44&"|"&$A45,'Master Data'!$A$2:$A$2436,0)),"") -> Tutup | Y45: =IFERROR(INDEX('Master Data'!$L$2:$L$2436,MATCH($B$3&"|3|"&G$44&"|"&$A45,'Master Data'!$A$2:$A$2436,0)),"") -> Tutup | Z45: =IFERROR(INDEX('Master Data'!$L$2:$L$2436,MATCH($B$3&"|3|"&H$44&"|"&$A45,'Master Data'!$A$2:$A$2436,0)),"") -> Tutup
...

Sheet KWC
A1: SLOT MAP · KWC · Karawaci
A2: Data per 26 Sep 2026 · sumber: Exboard › Reguler Class Availability
A3: Center | B3: KWC | C3: Center Manager
A4: Minggu | B4: W40 · 28 Sep – 4 Okt 2026 | C4: Senior Coach
A6: Ringkasan | B6: Utilisasi | C6: Kursi terisi | D6: Belum terisi | E6: Slot kosong | F6: Sebagian | G6: Penuh | H6: Lebih kapasitas
